Workbook
Name Acs: Constants!$B$30
Name Adc: Loop_Modeling!$B$35
Name Adc_ea: Loop_Modeling!$B$61
Name ADC_VINmin: Variable_Management!$B$189
Name CCOMP: Variable_Management!$B$230
Name CComp_calc: Variable_Management!$B$229
Name CHF: Variable_Management!$B$232
Name Comp_calc: Variable_Management!$B$229
Name CondMode: OFFSET(Lists!$B$9,0,0,COUNTIF(Lists!$B$9:$B$11,"?CM*"),1)
Name Cout: Variable_Management!$B$155
Name Cout_min: Variable_Management!$B$153
Name D_limit_max: Constants!$B$18
Name D_limit_min: Constants!$B$16
Name D_limit_nom: Constants!$B$17
Name Dc_CCM_VIN_max: Variable_Management!$B$50
Name Dc_CCM_VIN_min: Variable_Management!$B$42
Name Dc_CCM_VIN_nom: Variable_Management!$B$46
Name Dc_DCM_VIN_nom: Variable_Management!$B$62
Name Dc_max_IC: Variable_Management!$B$21
Name Dc_max_ideal: Variable_Management!$A$20
Name Dc_Mode: Variable_Management!$B$36
Name Dc_Mode_Loop: Loop_Modeling!$B$14
Name Dc_rip_max: Variable_Management!$B$79
Name Dc_VIN_max: Variable_Management!$B$31
Name Dc_VIN_min: Variable_Management!$B$23
Name Dc_VIN_nom: Variable_Management!$B$27
Name display_SCH: INDIRECT(Plot_Management_Sch!$A$1)
Name EFF_est: Variable_Management!$B$17
Name Eff_vs_IOUT: Plot_Management_Eff!$C$3
Name fcross: Variable_Management!$B$213
Name fcross_est: Variable_Management!$B$212
Name FIR_BYPASSED: '[1]Digital Filter'!$T$84
Name fp_ea_est: Variable_Management!$B$223
Name Fsw: Variable_Management!$B$10
Name fz_ea_est: Variable_Management!$B$221
Name fz_rhp: Variable_Management!$B$198
Name Gcomp: Constants!$B$29
Name Gea_mid_calc: Variable_Management!$B$217
Name gfs: Variable_Management!$B$249
Name gm_ea: Constants!$B$34
Name Gplant_fc_dB: Loop_Modeling!$AD$7
Name IIN_33: Variable_Management!$B$81
Name IL_avg_VIN_max: Variable_Management!$B$33
Name IL_avg_VIN_min: Variable_Management!$B$25
Name IL_avg_VIN_nom: Variable_Management!$B$29
Name IL_pk: Variable_Management!$B$142
Name IL_pk_max: Variable_Management!$B$143
Name ILp_VINmax: Variable_Management!$B$119
Name ILp_VINmin: Variable_Management!$B$113
Name ILp_VINnom: Variable_Management!$B$116
Name ILrip: Variable_Management!$B$71
Name ILrip_VINmax: Variable_Management!$B$118
Name ILrip_VINmin: Variable_Management!$B$112
Name ILrip_VINnom: Variable_Management!$B$115
Name IOUT: Variable_Management!$B$14
Name Ipk_margin: Variable_Management!$B$122
Name Ipk_selected: Variable_Management!$B$123
Name IQ: Constants!$B$48
Name IRMS_COUT: Variable_Management!$B$154
Name Isl: Constants!$B$25

Sheet Design Converter
E1: LM5155/56 DC/DC BOOST Controller Design Tool
A3: ABOUT | F3: =Input Box | N3: TERMS OF USE
N5: Rev 1.1.1 | O5: August-2021
A6: Step 1: Design Specifications
G7: Minimum Input Supply Voltage , VSUPPLY(min) | H7: 8 | I7: V
G8: Typical Input Supply Voltage, VSUPPLY(typ) | H8: 24 | I8: V
G9: Maximum Input Supply Voltage , VSUPPLY(max) | H9: 24 | I9: V
G10: Target Output Voltage, VLOAD | H10: 30 | I10: V
G11: Maximum Output Current , ILOAD | H11: 2 | I11: A
G12: Free Running Switching Frequency, FSW | H12: 750 | I12: kHz
G13: Free running Oscillator Set Resistor, RT | H13: =RT/1000 -> 28.511667 | I13: kΩ
G14: Estimated Efficiency | H14: 90 | I14: %
G15: Output Power, POUT | H15: =POUT -> 60 | I15: W
G16: Boost Converter Duty Cycle Limit by LM5155 at VSUPPLY(MIN) | H16: =Dc_max_IC*100 -> 93 | I16: %
G17: Ideal Duty Cycle at VSUPPLY(MIN) | H17: =Variable_Management!B39*100 -> 73.333333 | I17: %
G18: Operation Mode | H18: CCM
A20: Step 2: Filter Inductor
G21: Desired Maximum Inductor Current Ripple Ratio (IRR_MAX) | H21: 60 | I21: %
G22: Recommended Inductance (LM_CALC) | H22: =IF(H18="CCM",Lopt_2*10^6,L_DCM*10^6) -> 4.9379 | I22: μH
G23: User Selection. Inductance, (LM) | H23: 6.8 | I23: μH
G24: Max Inductor DCR, RDCR | H24: 20 | I24: mΩ
G25: Peak inductor current, ILPK | H25: =ILp_VINmin -> 8.9084967 | I25: A
A27: Step 3: Current Sense Resistor Selection
G28: Peak Current Limit Margin | H28: 20 | I28: %
G29: Selected Peak Current limit(ILPK_select) | H29: =Ipk_selected -> 10.690196 | I29: A
G30: Recommended current sense Resistor (RS) | H30: =Variable_Management!B135*1000 -> 9.3543654 | I30: mΩ
G31: Recommended external slope compensation Resistor (RSL) | H31: =Variable_Management!B136 -> 0 | I31: Ω
G32: Selected current sense Resistor (RS) | H32: 10 | I32: mΩ
G33: Selected external slope compensation Resistor (RSL) | H33: 267 | I33: Ω
G34: Actual inductor peak current limit | H34: =IL_pk_max -> 9.8398 | I34: A
G35: Recommend Minimum Inductor Saturation Current Rating | H35: =Variable_Management!B145 -> 11.31577 | I35: A
A37: Step 4: Output Capacitor Selection
G38: Desired Output ripple voltage (ΔvOUT) | H38: 10 | I38: mV
G39: Minimum output capacitance | H39: =Cout_min*10^6 -> 195.55556 | I39: μF
G40: Capacitor RMS current (IRMS_COUT) | H40: =IRMS_COUT -> 3.3343099 | I40: A
G41: Selected Output Capacitance (COUT) | H41: 1000 | I41: μF
G42: Equivalent COUT ESR (RESR) | H42: 5 | I42: mΩ
A44: Step 5: Soft-Start Capacitor Selection
G45: Suggested minimum soft-start capacitor (CSS_MIN) | H45: =Variable_Management!B161*(10^9) -> 150 | I45: nF
G46: Desired soft-start time at minimum input voltage (TSS) | H46: 20 | I46: ms
...

Sheet Variable_Management
A1: EXCEL Variables Names/Calculations
B2: Input from user =
B3: Output = | F3: Base Calculations of | G3: Spec conditions | H3: Nominal right now
B4: Constant
A5: Variable Name | B5: Value | C5: STD Units | E5: Notes | J5: Iteration | K5: Flag
A6: Step 1: Operational Specs
A7: VIN_min | B7: ='Design Converter'!H7 -> 8 | C7: V | E7: Minimum input voltage
A8: VIN_nom | B8: ='Design Converter'!H8 -> 24 | C8: V | E8: Nominal input voltage | K8: =IF(VIN_min<VIN_min,1,IF(VIN_nom>VIN_max,1,0)) -> 0
A9: VIN_max | B9: ='Design Converter'!H9 -> 24 | C9: V | E9: Maximum input voltage
A10: Fsw | B10: ='Design Converter'!H12*1000 -> 750000 | C10: Hz | E10: Switching frequnecy
A11: RT | B11: =((2.21*10^10)/Fsw)-955 -> 28511.667 | C11: Ω | E11: Oscillator Set resistor. Based on the datasheet equation
A13: VOUT | B13: ='Design Converter'!H10 -> 30 | C13: V | E13: Target Output Voltage
A14: IOUT | B14: ='Design Converter'!H11 -> 2 | C14: A | E14: Maximum Output current
A15: ROUT | B15: =VOUT/IOUT -> 15 | C15: Ω | E15: Minimum load resistance
A16: POUT | B16: =VOUT*IOUT -> 60 | C16: W | E16: Total output power
A17: EFF_est | B17: ='Design Converter'!H14/100 -> 0.9 | E17: Estimated efficiency
A19: CCM/DCM selected
A20: Dc_max_ideal | B20: =IF(B$36="DCM",B55,B39) -> 0.73333333 | E20: Maximum duty cycle at the minimum input voltage
A21: Dc_max_IC | B21: =Constants!B20 -> 0.93 | E21: Maximum IC duty cycle. Based on the forced off time. See Mathcad Calculations | K21: =IF(((1-D_limit_nom)/Constants!B12)<Fsw,1,0) -> 0
A23: Dc_VIN_min | B23: =IF(B$36="DCM",B58,B42) -> 0.73333333 | E23: Duty cycle at the mimum input voltage
B24: =IF(B$36="DCM",B59,B43) -> 9.7777778e-07 | C24: s | E24: On-time of the switch
A25: IL_avg_VIN_min | B25: =IF(B$36="DCM",B60,B44) -> 7.5 | C25: A | E25: Average input current at minimum input voltage. 100% Eff assumed | K25: V in min | L25: V in nom | M25: V in max
J26: DC CCM < DCM | K26: =Dc_CCM_VIN_min<B58 -> TRUE | L26: =Dc_CCM_VIN_nom<Dc_DCM_VIN_nom -> TRUE | M26: =Dc_CCM_VIN_max<B66 -> TRUE
A27: Dc_VIN_nom | B27: =IF(B$36="DCM",B62,B46) -> 0.2 | E27: Duty cycle at the nominal input voltage | J27: CCM only | K27: =AND(K26:M26) -> TRUE
B28: =IF(B$36="DCM",B63,B47) -> 2.6666667e-07 | C28: s | E28: On-time of the switch | J28: DCM only | K28: =NOT(OR(K26:M26)) -> FALSE
A29: IL_avg_VIN_nom | B29: =IF(B$36="DCM",B64,B48) -> 2.5 | C29: A | E29: Average input current at nominal input voltage. 100% Eff assumed | J29: CCM/DCM | K29: =NOT(OR(K27:K28)) -> FALSE
J30: ModeCheck | K30: =IF(Dc_Mode="CCM",K27,IF(Dc_Mode="DCM",K28,K29)) -> TRUE | P30: min10% | Q30: min | R30: max | S30: max10%
A31: Dc_VIN_max | B31: =IF(B$36="DCM",B66,B50) -> 0.2 | E31: Duty cycle at the maximum input voltage | K31: L dcm/ccm | L31: =VIN_min/(Fsw*2*IOUT)*Dc_VIN_min*(1-Dc_VIN_min) -> 5.2148148e-07 | M31: =VIN_nom/(Fsw*2*IOUT)*Dc_VIN_nom*(1-Dc_VIN_nom) -> 1.28e-06 | N31: =VIN_max/(Fsw*2*IOUT)*Dc_VIN_max*(1-Dc_VIN_max) -> 1.28e-06 | P31: =Q31*0.9 -> 4.6933333e-07 | Q31: =MIN(L31:N31) -> 5.2148148e-07 | R31: =MAX(L31:N31) -> 1.28e-06 | S31: =R31*1.1 -> 1.408e-06
B32: =IF(B$36="DCM",B67,B51) -> 2.6666667e-07 | C32: s | E32: On-time of the switch
A33: IL_avg_VIN_max | B33: =IF(B$36="DCM",B68,B52) -> 2.5 | C33: A | E33: Average input current at maximum input voltage. 100% Eff assumed
N34: Valid Lm
A35: ConductionMode | B35: =IF(AND(K35<Lm,L35<Lm,M35<Lm),"CCM",IF(AND(K35>Lm,L35>Lm,M35>Lm),"DCM","CCM/DCM")) -> CCM | E35: Possible Mode due to Load and L Selection | K35: =VIN_min/(Fsw*2*IOUT)*Dc_CCM_VIN_min*(1-Dc_CCM_VIN_min) -> 5.2148148e-07 | L35: =IF(AND(B50<0.5,B42>0.5),VIN_min/(Fsw*2*IOUT)*0.5*(1-0.5),VIN_min/(Fsw*2*IOUT)*Dc_CCM_VIN_nom*(1-Dc_CCM_VIN_nom)) -> 6.6666667e-07 | M35: =VIN_min/(Fsw*2*IOUT)*Dc_CCM_VIN_max*(1-Dc_VIN_max) -> 4.2666667e-07 | N35: =IF(Dc_Mode="CCM",IF(Lm<MAX(K35,L35,M35),TRUE,IF(Lm>MIN(K35,L35,M35),TRUE,FALSE))) -> TRUE
A36: Sel_Cond_Mode | B36: ='Design Converter'!H18 -> CCM | E36: Selected Mode for Calculation | K36: =IF(OR(B35="CCM",B35="CCM/DCM"),"CCM","DCM") -> CCM | L36: =IF(B35="CCM/DCM","DCM","")
A38: CCM
A39: Dc_CCM_max_ideal | B39: =1-VIN_min/VOUT -> 0.73333333 | E39: Maximum duty cycle at the minimum input voltage
A42: Dc_CCM_VIN_min | B42: =1-VIN_min/VOUT -> 0.73333333 | E42: Duty cycle at the mimum input voltage (CCM)
B43: =B42/Fsw -> 9.7777778e-07 | C43: s | E43: On-time of the switch
A44: IL_avg_CCM_VIN_min | B44: =(VOUT*IOUT)/(VIN_min) -> 7.5 | C44: A | E44: Average input current at minimum input voltage. 100% Eff assumed
A46: Dc_CCM_VIN_nom | B46: =1-VIN_nom/VOUT -> 0.2 | E46: Duty cycle at the nominal input voltage (CCM)
B47: =B46/Fsw -> 2.6666667e-07 | C47: s | E47: On-time of the switch
...

Sheet Eff_vs_IOUT
A1: EXCEL Variables Names/Calculations
R5: Operation Variables | V5: Duty Cycle | Y5: Inductor | AE5: MOSFET | AJ5: Diode | AO5: Other Losses | AR5: Total Losses
R6: VOUT | S6: IOUT | T6: VIN | U6: IIN | V6: DCM/CCM | W6: DC | X6: DC_off | Y6: dIL | Z6: ILPEAK | AA6: ILRMS | AB6: PLac (W) | AC6: PL_DCR (W) | AD6: PL_tot (W) | AE6: ISWAVG (A) | AF6: ISWRMS | AG6: PQ_COND (W) | AH6: PQ_SW (W) | AI6: PQ_tot (W) | AJ6: IDAVG (A) | AK6: IDRMS | AL6: PD_COND (W) | AM6: PD_SW (W) | AN6: PD_tot (W) | AO6: PRCS (W) | AP6: PG_drv (W) | AQ6: PIQ (W) | AR6: PTOTAL (W) | AS6: POUT (W) | AT6: Eff
Q7: 0 | R7: =VOUT -> 30 | S7: =Q7*$O$12 -> 0 | T7: =VIN_var -> 24 | U7: =(R7*S7)/(T7*EFF_est) -> 0 | V7: =IF((S7*R7/T7)<((T7*(1-(T7/R7)))/(2*Lm*Fsw)),1,2) -> 1 | W7: =CHOOSE(V7,SQRT((2*S7*Lm*Fsw*(R7-T7))/((T7)^2)),1-(T7/R7)) -> 0 | X7: =CHOOSE(V7,(Lm*W7*Fsw)/(R7-T7),1-W7) -> 0 | Y7: =(T7*W7)/(Lm*Fsw) -> 0 | Z7: =CHOOSE(V7,Y7,U7+(0.5*Y7)) -> 0 | AA7: =CHOOSE(V7,Z7*SQRT((W7+X7)/3),SQRT((U7^2)+((Y7^2)/12))) -> 0 | AB7: 0 | AC7: =(AA7^2)*Rdcr -> 0 | AD7: =AB7+AC7 -> 0 | AE7: =U7*W7 -> 0 | AF7: =CHOOSE(V7,Z7*SQRT(W7/3),SQRT(W7*((Z7^2)+((Y7^2)/3)-(Z7*Y7)))) -> 0 | AG7: =(AF7^2)*RDS_on -> 0 | AH7: =((R7*U7)/2)*Fsw*(tr_sw+tf_sw) -> 0 | AI7: =AG7+AH7 -> 0 | AJ7: =X7*U7 -> 0 | AK7: =CHOOSE(V7,Z7*SQRT(X7/3),SQRT(X7*((Z7^2)+((Y7^2)/3)-(Y7*Z7)))) -> 0 | AL7: =S7*Vd_rect -> 0 | AM7: =CHOOSE(V7,(R7+Vd_rect)*Qrr*Fsw,(R7+Vd_rect)*Qrr*Fsw) -> 0.22935 | AN7: =AL7+AM7 -> 0.22935 | AO7: =(AF7^2)*R_cs -> 0 | AP7: =Qg_tot*Vcc*Fsw -> 0.1994625 | AQ7: =IQ*T7 -> 0.0108 | AR7: =AO7+AN7+AI7+AD7+AP7+AQ7 -> 0.4396125 | AS7: =R7*S7 -> 0 | AT7: =(AS7/(AS7+AR7))*100 -> 0
M8: =Fsw -> 750000 | Q8: 1 | R8: =VOUT -> 30 | S8: =Q8*$O$12 -> 0.013333333 | T8: =VIN_var -> 24 | U8: =(R8*S8)/(T8*EFF_est) -> 0.018518519 | V8: =IF((S8*R8/T8)<((T8*(1-(T8/R8)))/(2*Lm*Fsw)),1,2) -> 1 | W8: =CHOOSE(V8,SQRT((2*S8*Lm*Fsw*(R8-T8))/((T8)^2)),1-(T8/R8)) -> 0.037638633 | X8: =CHOOSE(V8,(Lm*W8*Fsw)/(R8-T8),1-W8) -> 0.031992838 | Y8: =(T8*W8)/(Lm*Fsw) -> 0.17712298 | Z8: =CHOOSE(V8,Y8,U8+(0.5*Y8)) -> 0.17712298 | AA8: =CHOOSE(V8,Z8*SQRT((W8+X8)/3),SQRT((U8^2)+((Y8^2)/12))) -> 0.026984667 | AB8: 0 | AC8: =(AA8^2)*Rdcr -> 1.4563445e-05 | AD8: =AB8+AC8 -> 1.4563445e-05 | AE8: =U8*W8 -> 0.00069701172 | AF8: =CHOOSE(V8,Z8*SQRT(W8/3),SQRT(W8*((Z8^2)+((Y8^2)/3)-(Z8*Y8)))) -> 0.019839522 | AG8: =(AF8^2)*RDS_on -> 1.8105904e-06 | AH8: =((R8*U8)/2)*Fsw*(tr_sw+tf_sw) -> 0.0080966205 | AI8: =AG8+AH8 -> 0.0080984311 | AJ8: =X8*U8 -> 0.00059245996 | AK8: =CHOOSE(V8,Z8*SQRT(X8/3),SQRT(X8*((Z8^2)+((Y8^2)/3)-(Y8*Z8)))) -> 0.018291135 | AL8: =S8*Vd_rect -> 0.0077333333 | AM8: =CHOOSE(V8,(R8+Vd_rect)*Qrr*Fsw,(R8+Vd_rect)*Qrr*Fsw) -> 0.22935 | AN8: =AL8+AM8 -> 0.23708333 | AO8: =(AF8^2)*R_cs -> 3.9360662e-06 | AP8: =Qg_tot*Vcc*Fsw -> 0.1994625 | AQ8: =IQ*T8 -> 0.0108 | AR8: =AO8+AN8+AI8+AD8+AP8+AQ8 -> 0.45546276 | AS8: =R8*S8 -> 0.4 | AT8: =(AS8/(AS8+AR8))*100 -> 46.758318
N9: VIN_VAR | O9: =VIN_var -> 24 | P9: V | Q9: 2 | R9: =VOUT -> 30 | S9: =Q9*$O$12 -> 0.026666667 | T9: =VIN_var -> 24 | U9: =(R9*S9)/(T9*EFF_est) -> 0.037037037 | V9: =IF((S9*R9/T9)<((T9*(1-(T9/R9)))/(2*Lm*Fsw)),1,2) -> 1 | W9: =CHOOSE(V9,SQRT((2*S9*Lm*Fsw*(R9-T9))/((T9)^2)),1-(T9/R9)) -> 0.053229065 | X9: =CHOOSE(V9,(Lm*W9*Fsw)/(R9-T9),1-W9) -> 0.045244705 | Y9: =(T9*W9)/(Lm*Fsw) -> 0.25048972 | Z9: =CHOOSE(V9,Y9,U9+(0.5*Y9)) -> 0.25048972 | AA9: =CHOOSE(V9,Z9*SQRT((W9+X9)/3),SQRT((U9^2)+((Y9^2)/12))) -> 0.045382619 | AB9: 0 | AC9: =(AA9^2)*Rdcr -> 4.1191642e-05 | AD9: =AB9+AC9 -> 4.1191642e-05 | AE9: =U9*W9 -> 0.0019714468 | AF9: =CHOOSE(V9,Z9*SQRT(W9/3),SQRT(W9*((Z9^2)+((Y9^2)/3)-(Z9*Y9)))) -> 0.033365965 | AG9: =(AF9^2)*RDS_on -> 5.1211231e-06 | AH9: =((R9*U9)/2)*Fsw*(tr_sw+tf_sw) -> 0.016193241 | AI9: =AG9+AH9 -> 0.016198362 | AJ9: =X9*U9 -> 0.0016757298 | AK9: =CHOOSE(V9,Z9*SQRT(X9/3),SQRT(X9*((Z9^2)+((Y9^2)/3)-(Y9*Z9)))) -> 0.0307619 | AL9: =S9*Vd_rect -> 0.015466667 | AM9: =CHOOSE(V9,(R9+Vd_rect)*Qrr*Fsw,(R9+Vd_rect)*Qrr*Fsw) -> 0.22935 | AN9: =AL9+AM9 -> 0.24481667 | AO9: =(AF9^2)*R_cs -> 1.1132876e-05 | AP9: =Qg_tot*Vcc*Fsw -> 0.1994625 | AQ9: =IQ*T9 -> 0.0108 | AR9: =AO9+AN9+AI9+AD9+AP9+AQ9 -> 0.47132985 | AS9: =R9*S9 -> 0.8 | AT9: =(AS9/(AS9+AR9))*100 -> 62.926234
Q10: 3 | R10: =VOUT -> 30 | S10: =Q10*$O$12 -> 0.04 | T10: =VIN_var -> 24 | U10: =(R10*S10)/(T10*EFF_est) -> 0.055555556 | V10: =IF((S10*R10/T10)<((T10*(1-(T10/R10)))/(2*Lm*Fsw)),1,2) -> 1 | W10: =CHOOSE(V10,SQRT((2*S10*Lm*Fsw*(R10-T10))/((T10)^2)),1-(T10/R10)) -> 0.065192024 | X10: =CHOOSE(V10,(Lm*W10*Fsw)/(R10-T10),1-W10) -> 0.05541322 | Y10: =(T10*W10)/(Lm*Fsw) -> 0.306786 | Z10: =CHOOSE(V10,Y10,U10+(0.5*Y10)) -> 0.306786 | AA10: =CHOOSE(V10,Z10*SQRT((W10+X10)/3),SQRT((U10^2)+((Y10^2)/12))) -> 0.061511738 | AB10: 0 | AC10: =(AA10^2)*Rdcr -> 7.5673879e-05 | AD10: =AB10+AC10 -> 7.5673879e-05 | AE10: =U10*W10 -> 0.0036217791 | AF10: =CHOOSE(V10,Z10*SQRT(W10/3),SQRT(W10*((Z10^2)+((Y10^2)/3)-(Z10*Y10)))) -> 0.045224329 | AG10: =(AF10^2)*RDS_on -> 9.4081039e-06 | AH10: =((R10*U10)/2)*Fsw*(tr_sw+tf_sw) -> 0.024289862 | AI10: =AG10+AH10 -> 0.02429927 | AJ10: =X10*U10 -> 0.0030785122 | AK10: =CHOOSE(V10,Z10*SQRT(X10/3),SQRT(X10*((Z10^2)+((Y10^2)/3)-(Y10*Z10)))) -> 0.041694772 | AL10: =S10*Vd_rect -> 0.0232 | AM10: =CHOOSE(V10,(R10+Vd_rect)*Qrr*Fsw,(R10+Vd_rect)*Qrr*Fsw) -> 0.22935 | AN10: =AL10+AM10 -> 0.25255 | AO10: =(AF10^2)*R_cs -> 2.04524e-05 | AP10: =Qg_tot*Vcc*Fsw -> 0.1994625 | AQ10: =IQ*T10 -> 0.0108 | AR10: =AO10+AN10+AI10+AD10+AP10+AQ10 -> 0.4872079 | AS10: =R10*S10 -> 1.2 | AT10: =(AS10/(AS10+AR10))*100 -> 71.123422
N11: Steps | O11: 150 | Q11: 4 | R11: =VOUT -> 30 | S11: =Q11*$O$12 -> 0.053333333 | T11: =VIN_var -> 24 | U11: =(R11*S11)/(T11*EFF_est) -> 0.074074074 | V11: =IF((S11*R11/T11)<((T11*(1-(T11/R11)))/(2*Lm*Fsw)),1,2) -> 1 | W11: =CHOOSE(V11,SQRT((2*S11*Lm*Fsw*(R11-T11))/((T11)^2)),1-(T11/R11)) -> 0.075277265 | X11: =CHOOSE(V11,(Lm*W11*Fsw)/(R11-T11),1-W11) -> 0.063985675 | Y11: =(T11*W11)/(Lm*Fsw) -> 0.35424595 | Z11: =CHOOSE(V11,Y11,U11+(0.5*Y11)) -> 0.35424595 | AA11: =CHOOSE(V11,Z11*SQRT((W11+X11)/3),SQRT((U11^2)+((Y11^2)/12))) -> 0.076324163 | AB11: 0 | AC11: =(AA11^2)*Rdcr -> 0.00011650756 | AD11: =AB11+AC11 -> 0.00011650756 | AE11: =U11*W11 -> 0.0055760937 | AF11: =CHOOSE(V11,Z11*SQRT(W11/3),SQRT(W11*((Z11^2)+((Y11^2)/3)-(Z11*Y11)))) -> 0.056114641 | AG11: =(AF11^2)*RDS_on -> 1.4484723e-05 | AH11: =((R11*U11)/2)*Fsw*(tr_sw+tf_sw) -> 0.032386482 | AI11: =AG11+AH11 -> 0.032400967 | AJ11: =X11*U11 -> 0.0047396797 | AK11: =CHOOSE(V11,Z11*SQRT(X11/3),SQRT(X11*((Z11^2)+((Y11^2)/3)-(Y11*Z11)))) -> 0.051735143 | AL11: =S11*Vd_rect -> 0.030933333 | AM11: =CHOOSE(V11,(R11+Vd_rect)*Qrr*Fsw,(R11+Vd_rect)*Qrr*Fsw) -> 0.22935 | AN11: =AL11+AM11 -> 0.26028333 | AO11: =(AF11^2)*R_cs -> 3.1488529e-05 | AP11: =Qg_tot*Vcc*Fsw -> 0.1994625 | AQ11: =IQ*T11 -> 0.0108 | AR11: =AO11+AN11+AI11+AD11+AP11+AQ11 -> 0.5030948 | AS11: =R11*S11 -> 1.6 | AT11: =(AS11/(AS11+AR11))*100 -> 76.078359
N12: Step size | O12: =IOUT/(O11) -> 0.013333333 | Q12: 5 | R12: =VOUT -> 30 | S12: =Q12*$O$12 -> 0.066666667 | T12: =VIN_var -> 24 | U12: =(R12*S12)/(T12*EFF_est) -> 0.092592593 | V12: =IF((S12*R12/T12)<((T12*(1-(T12/R12)))/(2*Lm*Fsw)),1,2) -> 1 | W12: =CHOOSE(V12,SQRT((2*S12*Lm*Fsw*(R12-T12))/((T12)^2)),1-(T12/R12)) -> 0.084162541 | X12: =CHOOSE(V12,(Lm*W12*Fsw)/(R12-T12),1-W12) -> 0.07153816 | Y12: =(T12*W12)/(Lm*Fsw) -> 0.39605902 | Z12: =CHOOSE(V12,Y12,U12+(0.5*Y12)) -> 0.39605902 | AA12: =CHOOSE(V12,Z12*SQRT((W12+X12)/3),SQRT((U12^2)+((Y12^2)/12))) -> 0.090228671 | AB12: 0 | AC12: =(AA12^2)*Rdcr -> 0.00016282426 | AD12: =AB12+AC12 -> 0.00016282426 | AE12: =U12*W12 -> 0.0077928279 | AF12: =CHOOSE(V12,Z12*SQRT(W12/3),SQRT(W12*((Z12^2)+((Y12^2)/3)-(Z12*Y12)))) -> 0.066337438 | AG12: =(AF12^2)*RDS_on -> 2.0243016e-05 | AH12: =((R12*U12)/2)*Fsw*(tr_sw+tf_sw) -> 0.040483103 | AI12: =AG12+AH12 -> 0.040503346 | AJ12: =X12*U12 -> 0.0066239037 | AK12: =CHOOSE(V12,Z12*SQRT(X12/3),SQRT(X12*((Z12^2)+((Y12^2)/3)-(Y12*Z12)))) -> 0.061160096 | AL12: =S12*Vd_rect -> 0.038666667 | AM12: =CHOOSE(V12,(R12+Vd_rect)*Qrr*Fsw,(R12+Vd_rect)*Qrr*Fsw) -> 0.22935 | AN12: =AL12+AM12 -> 0.26801667 | AO12: =(AF12^2)*R_cs -> 4.4006557e-05 | AP12: =Qg_tot*Vcc*Fsw -> 0.1994625 | AQ12: =IQ*T12 -> 0.0108 | AR12: =AO12+AN12+AI12+AD12+AP12+AQ12 -> 0.51898934 | AS12: =R12*S12 -> 2 | AT12: =(AS12/(AS12+AR12))*100 -> 79.396922
Q13: 6 | R13: =VOUT -> 30 | S13: =Q13*$O$12 -> 0.08 | T13: =VIN_var -> 24 | U13: =(R13*S13)/(T13*EFF_est) -> 0.11111111 | V13: =IF((S13*R13/T13)<((T13*(1-(T13/R13)))/(2*Lm*Fsw)),1,2) -> 1 | W13: =CHOOSE(V13,SQRT((2*S13*Lm*Fsw*(R13-T13))/((T13)^2)),1-(T13/R13)) -> 0.092195445 | X13: =CHOOSE(V13,(Lm*W13*Fsw)/(R13-T13),1-W13) -> 0.078366128 | Y13: =(T13*W13)/(Lm*Fsw) -> 0.43386092 | Z13: =CHOOSE(V13,Y13,U13+(0.5*Y13)) -> 0.43386092 | AA13: =CHOOSE(V13,Z13*SQRT((W13+X13)/3),SQRT((U13^2)+((Y13^2)/12))) -> 0.10345 | AB13: 0 | AC13: =(AA13^2)*Rdcr -> 0.00021403805 | AD13: =AB13+AC13 -> 0.00021403805 | AE13: =U13*W13 -> 0.010243938 | AF13: =CHOOSE(V13,Z13*SQRT(W13/3),SQRT(W13*((Z13^2)+((Y13^2)/3)-(Z13*Y13)))) -> 0.076057953 | AG13: =(AF13^2)*RDS_on -> 2.6610136e-05 | AH13: =((R13*U13)/2)*Fsw*(tr_sw+tf_sw) -> 0.048579723 | AI13: =AG13+AH13 -> 0.048606333 | AJ13: =X13*U13 -> 0.0087073475 | AK13: =CHOOSE(V13,Z13*SQRT(X13/3),SQRT(X13*((Z13^2)+((Y13^2)/3)-(Y13*Z13)))) -> 0.070121968 | AL13: =S13*Vd_rect -> 0.0464 | AM13: =CHOOSE(V13,(R13+Vd_rect)*Qrr*Fsw,(R13+Vd_rect)*Qrr*Fsw) -> 0.22935 | AN13: =AL13+AM13 -> 0.27575 | AO13: =(AF13^2)*R_cs -> 5.7848122e-05 | AP13: =Qg_tot*Vcc*Fsw -> 0.1994625 | AQ13: =IQ*T13 -> 0.0108 | AR13: =AO13+AN13+AI13+AD13+AP13+AQ13 -> 0.53489072 | AS13: =R13*S13 -> 2.4 | AT13: =(AS13/(AS13+AR13))*100 -> 81.774765
Q14: 7 | R14: =VOUT -> 30 | S14: =Q14*$O$12 -> 0.093333333 | T14: =VIN_var -> 24 | U14: =(R14*S14)/(T14*EFF_est) -> 0.12962963 | V14: =IF((S14*R14/T14)<((T14*(1-(T14/R14)))/(2*Lm*Fsw)),1,2) -> 1 | W14: =CHOOSE(V14,SQRT((2*S14*Lm*Fsw*(R14-T14))/((T14)^2)),1-(T14/R14)) -> 0.099582462 | X14: =CHOOSE(V14,(Lm*W14*Fsw)/(R14-T14),1-W14) -> 0.084645092 | Y14: =(T14*W14)/(Lm*Fsw) -> 0.46862335 | Z14: =CHOOSE(V14,Y14,U14+(0.5*Y14)) -> 0.46862335 | AA14: =CHOOSE(V14,Z14*SQRT((W14+X14)/3),SQRT((U14^2)+((Y14^2)/12))) -> 0.11612897 | AB14: 0 | AC14: =(AA14^2)*Rdcr -> 0.00026971877 | AD14: =AB14+AC14 -> 0.00026971877 | AE14: =U14*W14 -> 0.012908838 | AF14: =CHOOSE(V14,Z14*SQRT(W14/3),SQRT(W14*((Z14^2)+((Y14^2)/3)-(Z14*Y14)))) -> 0.08537972 | AG14: =(AF14^2)*RDS_on -> 3.3532604e-05 | AH14: =((R14*U14)/2)*Fsw*(tr_sw+tf_sw) -> 0.056676344 | AI14: =AG14+AH14 -> 0.056709876 | AJ14: =X14*U14 -> 0.010972512 | AK14: =CHOOSE(V14,Z14*SQRT(X14/3),SQRT(X14*((Z14^2)+((Y14^2)/3)-(Y14*Z14)))) -> 0.078716212 | AL14: =S14*Vd_rect -> 0.054133333 | AM14: =CHOOSE(V14,(R14+Vd_rect)*Qrr*Fsw,(R14+Vd_rect)*Qrr*Fsw) -> 0.22935 | AN14: =AL14+AM14 -> 0.28348333 | AO14: =(AF14^2)*R_cs -> 7.2896965e-05 | AP14: =Qg_tot*Vcc*Fsw -> 0.1994625 | AQ14: =IQ*T14 -> 0.0108 | AR14: =AO14+AN14+AI14+AD14+AP14+AQ14 -> 0.55079833 | AS14: =R14*S14 -> 2.8 | AT14: =(AS14/(AS14+AR14))*100 -> 83.562176
O15: =0.205*2.5/(Lm*Fsw) -> 0.1004902 | Q15: 8 | R15: =VOUT -> 30 | S15: =Q15*$O$12 -> 0.10666667 | T15: =VIN_var -> 24 | U15: =(R15*S15)/(T15*EFF_est) -> 0.14814815 | V15: =IF((S15*R15/T15)<((T15*(1-(T15/R15)))/(2*Lm*Fsw)),1,2) -> 1 | W15: =CHOOSE(V15,SQRT((2*S15*Lm*Fsw*(R15-T15))/((T15)^2)),1-(T15/R15)) -> 0.10645813 | X15: =CHOOSE(V15,(Lm*W15*Fsw)/(R15-T15),1-W15) -> 0.09048941 | Y15: =(T15*W15)/(Lm*Fsw) -> 0.50097943 | Z15: =CHOOSE(V15,Y15,U15+(0.5*Y15)) -> 0.50097943 | AA15: =CHOOSE(V15,Z15*SQRT((W15+X15)/3),SQRT((U15^2)+((Y15^2)/12))) -> 0.12836143 | AB15: 0 | AC15: =(AA15^2)*Rdcr -> 0.00032953314 | AD15: =AB15+AC15 -> 0.00032953314 | AE15: =U15*W15 -> 0.015771575 | AF15: =CHOOSE(V15,Z15*SQRT(W15/3),SQRT(W15*((Z15^2)+((Y15^2)/3)-(Z15*Y15)))) -> 0.094373201 | AG15: =(AF15^2)*RDS_on -> 4.0968985e-05 | AH15: =((R15*U15)/2)*Fsw*(tr_sw+tf_sw) -> 0.064772964 | AI15: =AG15+AH15 -> 0.064813933 | AJ15: =X15*U15 -> 0.013405839 | AK15: =CHOOSE(V15,Z15*SQRT(X15/3),SQRT(X15*((Z15^2)+((Y15^2)/3)-(Y15*Z15)))) -> 0.087007792 | AL15: =S15*Vd_rect -> 0.061866667 | AM15: =CHOOSE(V15,(R15+Vd_rect)*Qrr*Fsw,(R15+Vd_rect)*Qrr*Fsw) -> 0.22935 | AN15: =AL15+AM15 -> 0.29121667 | AO15: =(AF15^2)*R_cs -> 8.906301e-05 | AP15: =Qg_tot*Vcc*Fsw -> 0.1994625 | AQ15: =IQ*T15 -> 0.0108 | AR15: =AO15+AN15+AI15+AD15+AP15+AQ15 -> 0.5667117 | AS15: =R15*S15 -> 3.2 | AT15: =(AS15/(AS15+AR15))*100 -> 84.954737
Q16: 9 | R16: =VOUT -> 30 | S16: =Q16*$O$12 -> 0.12 | T16: =VIN_var -> 24 | U16: =(R16*S16)/(T16*EFF_est) -> 0.16666667 | V16: =IF((S16*R16/T16)<((T16*(1-(T16/R16)))/(2*Lm*Fsw)),1,2) -> 1 | W16: =CHOOSE(V16,SQRT((2*S16*Lm*Fsw*(R16-T16))/((T16)^2)),1-(T16/R16)) -> 0.1129159 | X16: =CHOOSE(V16,(Lm*W16*Fsw)/(R16-T16),1-W16) -> 0.095978513 | Y16: =(T16*W16)/(Lm*Fsw) -> 0.53136893 | Z16: =CHOOSE(V16,Y16,U16+(0.5*Y16)) -> 0.53136893 | AA16: =CHOOSE(V16,Z16*SQRT((W16+X16)/3),SQRT((U16^2)+((Y16^2)/12))) -> 0.14021644 | AB16: 0 | AC16: =(AA16^2)*Rdcr -> 0.00039321301 | AD16: =AB16+AC16 -> 0.00039321301 | AE16: =U16*W16 -> 0.018819316 | AF16: =CHOOSE(V16,Z16*SQRT(W16/3),SQRT(W16*((Z16^2)+((Y16^2)/3)-(Z16*Y16)))) -> 0.10308918 | AG16: =(AF16^2)*RDS_on -> 4.8885942e-05 | AH16: =((R16*U16)/2)*Fsw*(tr_sw+tf_sw) -> 0.072869585 | AI16: =AG16+AH16 -> 0.072918471 | AJ16: =X16*U16 -> 0.015996419 | AK16: =CHOOSE(V16,Z16*SQRT(X16/3),SQRT(X16*((Z16^2)+((Y16^2)/3)-(Y16*Z16)))) -> 0.095043526 | AL16: =S16*Vd_rect -> 0.0696 | AM16: =CHOOSE(V16,(R16+Vd_rect)*Qrr*Fsw,(R16+Vd_rect)*Qrr*Fsw) -> 0.22935 | AN16: =AL16+AM16 -> 0.29895 | AO16: =(AF16^2)*R_cs -> 0.00010627379 | AP16: =Qg_tot*Vcc*Fsw -> 0.1994625 | AQ16: =IQ*T16 -> 0.0108 | AR16: =AO16+AN16+AI16+AD16+AP16+AQ16 -> 0.58263046 | AS16: =R16*S16 -> 3.6 | AT16: =(AS16/(AS16+AR16))*100 -> 86.070238
Q17: 10 | R17: =VOUT -> 30 | S17: =Q17*$O$12 -> 0.13333333 | T17: =VIN_var -> 24 | U17: =(R17*S17)/(T17*EFF_est) -> 0.18518519 | V17: =IF((S17*R17/T17)<((T17*(1-(T17/R17)))/(2*Lm*Fsw)),1,2) -> 1 | W17: =CHOOSE(V17,SQRT((2*S17*Lm*Fsw*(R17-T17))/((T17)^2)),1-(T17/R17)) -> 0.11902381 | X17: =CHOOSE(V17,(Lm*W17*Fsw)/(R17-T17),1-W17) -> 0.10117024 | Y17: =(T17*W17)/(Lm*Fsw) -> 0.56011203 | Z17: =CHOOSE(V17,Y17,U17+(0.5*Y17)) -> 0.56011203 | AA17: =CHOOSE(V17,Z17*SQRT((W17+X17)/3),SQRT((U17^2)+((Y17^2)/12))) -> 0.15174593 | AB17: 0 | AC17: =(AA17^2)*Rdcr -> 0.00046053656 | AD17: =AB17+AC17 -> 0.00046053656 | AE17: =U17*W17 -> 0.022041446 | AF17: =CHOOSE(V17,Z17*SQRT(W17/3),SQRT(W17*((Z17^2)+((Y17^2)/3)-(Z17*Y17)))) -> 0.11156583 | AG17: =(AF17^2)*RDS_on -> 5.7255897e-05 | AH17: =((R17*U17)/2)*Fsw*(tr_sw+tf_sw) -> 0.080966205 | AI17: =AG17+AH17 -> 0.081023461 | AJ17: =X17*U17 -> 0.018735229 | AK17: =CHOOSE(V17,Z17*SQRT(X17/3),SQRT(X17*((Z17^2)+((Y17^2)/3)-(Y17*Z17)))) -> 0.10285861 | AL17: =S17*Vd_rect -> 0.077333333 | AM17: =CHOOSE(V17,(R17+Vd_rect)*Qrr*Fsw,(R17+Vd_rect)*Qrr*Fsw) -> 0.22935 | AN17: =AL17+AM17 -> 0.30668333 | AO17: =(AF17^2)*R_cs -> 0.00012446934 | AP17: =Qg_tot*Vcc*Fsw -> 0.1994625 | AQ17: =IQ*T17 -> 0.0108 | AR17: =AO17+AN17+AI17+AD17+AP17+AQ17 -> 0.5985543 | AS17: =R17*S17 -> 4 | AT17: =(AS17/(AS17+AR17))*100 -> 86.983859
Q18: 11 | R18: =VOUT -> 30 | S18: =Q18*$O$12 -> 0.14666667 | T18: =VIN_var -> 24 | U18: =(R18*S18)/(T18*EFF_est) -> 0.2037037 | V18: =IF((S18*R18/T18)<((T18*(1-(T18/R18)))/(2*Lm*Fsw)),1,2) -> 1 | W18: =CHOOSE(V18,SQRT((2*S18*Lm*Fsw*(R18-T18))/((T18)^2)),1-(T18/R18)) -> 0.12483322 | X18: =CHOOSE(V18,(Lm*W18*Fsw)/(R18-T18),1-W18) -> 0.10610824 | Y18: =(T18*W18)/(Lm*Fsw) -> 0.58745046 | Z18: =CHOOSE(V18,Y18,U18+(0.5*Y18)) -> 0.58745046 | AA18: =CHOOSE(V18,Z18*SQRT((W18+X18)/3),SQRT((U18^2)+((Y18^2)/12))) -> 0.16299023 | AB18: 0 | AC18: =(AA18^2)*Rdcr -> 0.0005313163 | AD18: =AB18+AC18 -> 0.0005313163 | AE18: =U18*W18 -> 0.02542899 | AF18: =CHOOSE(V18,Z18*SQRT(W18/3),SQRT(W18*((Z18^2)+((Y18^2)/3)-(Z18*Y18)))) -> 0.1198328 | AG18: =(AF18^2)*RDS_on -> 6.605554e-05 | AH18: =((R18*U18)/2)*Fsw*(tr_sw+tf_sw) -> 0.089062826 | AI18: =AG18+AH18 -> 0.089128881 | AJ18: =X18*U18 -> 0.021614641 | AK18: =CHOOSE(V18,Z18*SQRT(X18/3),SQRT(X18*((Z18^2)+((Y18^2)/3)-(Y18*Z18)))) -> 0.11048038 | AL18: =S18*Vd_rect -> 0.085066667 | AM18: =CHOOSE(V18,(R18+Vd_rect)*Qrr*Fsw,(R18+Vd_rect)*Qrr*Fsw) -> 0.22935 | AN18: =AL18+AM18 -> 0.31441667 | AO18: =(AF18^2)*R_cs -> 0.000143599 | AP18: =Qg_tot*Vcc*Fsw -> 0.1994625 | AQ18: =IQ*T18 -> 0.0108 | AR18: =AO18+AN18+AI18+AD18+AP18+AQ18 -> 0.61448296 | AS18: =R18*S18 -> 4.4 | AT18: =(AS18/(AS18+AR18))*100 -> 87.745836
Q19: 12 | R19: =VOUT -> 30 | S19: =Q19*$O$12 -> 0.16 | T19: =VIN_var -> 24 | U19: =(R19*S19)/(T19*EFF_est) -> 0.22222222 | V19: =IF((S19*R19/T19)<((T19*(1-(T19/R19)))/(2*Lm*Fsw)),1,2) -> 1 | W19: =CHOOSE(V19,SQRT((2*S19*Lm*Fsw*(R19-T19))/((T19)^2)),1-(T19/R19)) -> 0.13038405 | X19: =CHOOSE(V19,(Lm*W19*Fsw)/(R19-T19),1-W19) -> 0.11082644 | Y19: =(T19*W19)/(Lm*Fsw) -> 0.61357199 | Z19: =CHOOSE(V19,Y19,U19+(0.5*Y19)) -> 0.61357199 | AA19: =CHOOSE(V19,Z19*SQRT((W19+X19)/3),SQRT((U19^2)+((Y19^2)/12))) -> 0.17398147 | AB19: 0 | AC19: =(AA19^2)*Rdcr -> 0.00060539103 | AD19: =AB19+AC19 -> 0.00060539103 | AE19: =U19*W19 -> 0.028974233 | AF19: =CHOOSE(V19,Z19*SQRT(W19/3),SQRT(W19*((Z19^2)+((Y19^2)/3)-(Z19*Y19)))) -> 0.12791372 | AG19: =(AF19^2)*RDS_on -> 7.5264831e-05 | AH19: =((R19*U19)/2)*Fsw*(tr_sw+tf_sw) -> 0.097159446 | AI19: =AG19+AH19 -> 0.097234711 | AJ19: =X19*U19 -> 0.024628098 | AK19: =CHOOSE(V19,Z19*SQRT(X19/3),SQRT(X19*((Z19^2)+((Y19^2)/3)-(Y19*Z19)))) -> 0.11793062 | AL19: =S19*Vd_rect -> 0.0928 | AM19: =CHOOSE(V19,(R19+Vd_rect)*Qrr*Fsw,(R19+Vd_rect)*Qrr*Fsw) -> 0.22935 | AN19: =AL19+AM19 -> 0.32215 | AO19: =(AF19^2)*R_cs -> 0.0001636192 | AP19: =Qg_tot*Vcc*Fsw -> 0.1994625 | AQ19: =IQ*T19 -> 0.0108 | AR19: =AO19+AN19+AI19+AD19+AP19+AQ19 -> 0.63041622 | AS19: =R19*S19 -> 4.8 | AT19: =(AS19/(AS19+AR19))*100 -> 88.391015
Q20: 13 | R20: =VOUT -> 30 | S20: =Q20*$O$12 -> 0.17333333 | T20: =VIN_var -> 24 | U20: =(R20*S20)/(T20*EFF_est) -> 0.24074074 | V20: =IF((S20*R20/T20)<((T20*(1-(T20/R20)))/(2*Lm*Fsw)),1,2) -> 1 | W20: =CHOOSE(V20,SQRT((2*S20*Lm*Fsw*(R20-T20))/((T20)^2)),1-(T20/R20)) -> 0.13570802 | X20: =CHOOSE(V20,(Lm*W20*Fsw)/(R20-T20),1-W20) -> 0.11535182 | Y20: =(T20*W20)/(Lm*Fsw) -> 0.63862598 | Z20: =CHOOSE(V20,Y20,U20+(0.5*Y20)) -> 0.63862598 | AA20: =CHOOSE(V20,Z20*SQRT((W20+X20)/3),SQRT((U20^2)+((Y20^2)/12))) -> 0.1847458 | AB20: 0 | AC20: =(AA20^2)*Rdcr -> 0.00068262021 | AD20: =AB20+AC20 -> 0.00068262021 | AE20: =U20*W20 -> 0.032670449 | AF20: =CHOOSE(V20,Z20*SQRT(W20/3),SQRT(W20*((Z20^2)+((Y20^2)/3)-(Z20*Y20)))) -> 0.13582781 | AG20: =(AF20^2)*RDS_on -> 8.4866296e-05 | AH20: =((R20*U20)/2)*Fsw*(tr_sw+tf_sw) -> 0.10525607 | AI20: =AG20+AH20 -> 0.10534093 | AJ20: =X20*U20 -> 0.027769882 | AK20: =CHOOSE(V20,Z20*SQRT(X20/3),SQRT(X20*((Z20^2)+((Y20^2)/3)-(Y20*Z20)))) -> 0.12522706 | AL20: =S20*Vd_rect -> 0.10053333 | AM20: =CHOOSE(V20,(R20+Vd_rect)*Qrr*Fsw,(R20+Vd_rect)*Qrr*Fsw) -> 0.22935 | AN20: =AL20+AM20 -> 0.32988333 | AO20: =(AF20^2)*R_cs -> 0.00018449195 | AP20: =Qg_tot*Vcc*Fsw -> 0.1994625 | AQ20: =IQ*T20 -> 0.0108 | AR20: =AO20+AN20+AI20+AD20+AP20+AQ20 -> 0.64635388 | AS20: =R20*S20 -> 5.2 | AT20: =(AS20/(AS20+AR20))*100 -> 88.944325
Q21: 14 | R21: =VOUT -> 30 | S21: =Q21*$O$12 -> 0.18666667 | T21: =VIN_var -> 24 | U21: =(R21*S21)/(T21*EFF_est) -> 0.25925926 | V21: =IF((S21*R21/T21)<((T21*(1-(T21/R21)))/(2*Lm*Fsw)),1,2) -> 1 | W21: =CHOOSE(V21,SQRT((2*S21*Lm*Fsw*(R21-T21))/((T21)^2)),1-(T21/R21)) -> 0.14083087 | X21: =CHOOSE(V21,(Lm*W21*Fsw)/(R21-T21),1-W21) -> 0.11970624 | Y21: =(T21*W21)/(Lm*Fsw) -> 0.6627335 | Z21: =CHOOSE(V21,Y21,U21+(0.5*Y21)) -> 0.6627335 | AA21: =CHOOSE(V21,Z21*SQRT((W21+X21)/3),SQRT((U21^2)+((Y21^2)/12))) -> 0.19530488 | AB21: 0 | AC21: =(AA21^2)*Rdcr -> 0.00076287989 | AD21: =AB21+AC21 -> 0.00076287989 | AE21: =U21*W21 -> 0.036511706 | AF21: =CHOOSE(V21,Z21*SQRT(W21/3),SQRT(W21*((Z21^2)+((Y21^2)/3)-(Z21*Y21)))) -> 0.143591 | AG21: =(AF21^2)*RDS_on -> 9.4844527e-05 | AH21: =((R21*U21)/2)*Fsw*(tr_sw+tf_sw) -> 0.11335269 | AI21: =AG21+AH21 -> 0.11344753 | AJ21: =X21*U21 -> 0.031034951 | AK21: =CHOOSE(V21,Z21*SQRT(X21/3),SQRT(X21*((Z21^2)+((Y21^2)/3)-(Y21*Z21)))) -> 0.13238436 | AL21: =S21*Vd_rect -> 0.10826667 | AM21: =CHOOSE(V21,(R21+Vd_rect)*Qrr*Fsw,(R21+Vd_rect)*Qrr*Fsw) -> 0.22935 | AN21: =AL21+AM21 -> 0.33761667 | AO21: =(AF21^2)*R_cs -> 0.00020618375 | AP21: =Qg_tot*Vcc*Fsw -> 0.1994625 | AQ21: =IQ*T21 -> 0.0108 | AR21: =AO21+AN21+AI21+AD21+AP21+AQ21 -> 0.66229576 | AS21: =R21*S21 -> 5.6 | AT21: =(AS21/(AS21+AR21))*100 -> 89.424074
Q22: 15 | R22: =VOUT -> 30 | S22: =Q22*$O$12 -> 0.2 | T22: =VIN_var -> 24 | U22: =(R22*S22)/(T22*EFF_est) -> 0.27777778 | V22: =IF((S22*R22/T22)<((T22*(1-(T22/R22)))/(2*Lm*Fsw)),1,2) -> 1 | W22: =CHOOSE(V22,SQRT((2*S22*Lm*Fsw*(R22-T22))/((T22)^2)),1-(T22/R22)) -> 0.1457738 | X22: =CHOOSE(V22,(Lm*W22*Fsw)/(R22-T22),1-W22) -> 0.12390773 | Y22: =(T22*W22)/(Lm*Fsw) -> 0.68599434 | Z22: =CHOOSE(V22,Y22,U22+(0.5*Y22)) -> 0.68599434 | AA22: =CHOOSE(V22,Z22*SQRT((W22+X22)/3),SQRT((U22^2)+((Y22^2)/12))) -> 0.20567689 | AB22: 0 | AC22: =(AA22^2)*Rdcr -> 0.00084605969 | AD22: =AB22+AC22 -> 0.00084605969 | AE22: =U22*W22 -> 0.040492721 | AF22: =CHOOSE(V22,Z22*SQRT(W22/3),SQRT(W22*((Z22^2)+((Y22^2)/3)-(Z22*Y22)))) -> 0.15121666 | AG22: =(AF22^2)*RDS_on -> 0.0001051858 | AH22: =((R22*U22)/2)*Fsw*(tr_sw+tf_sw) -> 0.12144931 | AI22: =AG22+AH22 -> 0.12155449 | AJ22: =X22*U22 -> 0.034418813 | AK22: =CHOOSE(V22,Z22*SQRT(X22/3),SQRT(X22*((Z22^2)+((Y22^2)/3)-(Y22*Z22)))) -> 0.13941487 | AL22: =S22*Vd_rect -> 0.116 | AM22: =CHOOSE(V22,(R22+Vd_rect)*Qrr*Fsw,(R22+Vd_rect)*Qrr*Fsw) -> 0.22935 | AN22: =AL22+AM22 -> 0.34535 | AO22: =(AF22^2)*R_cs -> 0.00022866478 | AP22: =Qg_tot*Vcc*Fsw -> 0.1994625 | AQ22: =IQ*T22 -> 0.0108 | AR22: =AO22+AN22+AI22+AD22+AP22+AQ22 -> 0.67824172 | AS22: =R22*S22 -> 6 | AT22: =(AS22/(AS22+AR22))*100 -> 89.844008
Q23: 16 | R23: =VOUT -> 30 | S23: =Q23*$O$12 -> 0.21333333 | T23: =VIN_var -> 24 | U23: =(R23*S23)/(T23*EFF_est) -> 0.2962963 | V23: =IF((S23*R23/T23)<((T23*(1-(T23/R23)))/(2*Lm*Fsw)),1,2) -> 1 | W23: =CHOOSE(V23,SQRT((2*S23*Lm*Fsw*(R23-T23))/((T23)^2)),1-(T23/R23)) -> 0.15055453 | X23: =CHOOSE(V23,(Lm*W23*Fsw)/(R23-T23),1-W23) -> 0.12797135 | Y23: =(T23*W23)/(Lm*Fsw) -> 0.70849191 | Z23: =CHOOSE(V23,Y23,U23+(0.5*Y23)) -> 0.70849191 | AA23: =CHOOSE(V23,Z23*SQRT((W23+X23)/3),SQRT((U23^2)+((Y23^2)/12))) -> 0.21587733 | AB23: 0 | AC23: =(AA23^2)*Rdcr -> 0.00093206047 | AD23: =AB23+AC23 -> 0.00093206047 | AE23: =U23*W23 -> 0.04460875 | AF23: =CHOOSE(V23,Z23*SQRT(W23/3),SQRT(W23*((Z23^2)+((Y23^2)/3)-(Z23*Y23)))) -> 0.15871617 | AG23: =(AF23^2)*RDS_on -> 0.00011587779 | AH23: =((R23*U23)/2)*Fsw*(tr_sw+tf_sw) -> 0.12954593 | AI23: =AG23+AH23 -> 0.12966181 | AJ23: =X23*U23 -> 0.037917437 | AK23: =CHOOSE(V23,Z23*SQRT(X23/3),SQRT(X23*((Z23^2)+((Y23^2)/3)-(Y23*Z23)))) -> 0.14632908 | AL23: =S23*Vd_rect -> 0.12373333 | AM23: =CHOOSE(V23,(R23+Vd_rect)*Qrr*Fsw,(R23+Vd_rect)*Qrr*Fsw) -> 0.22935 | AN23: =AL23+AM23 -> 0.35308333 | AO23: =(AF23^2)*R_cs -> 0.00025190823 | AP23: =Qg_tot*Vcc*Fsw -> 0.1994625 | AQ23: =IQ*T23 -> 0.0108 | AR23: =AO23+AN23+AI23+AD23+AP23+AQ23 -> 0.69419161 | AS23: =R23*S23 -> 6.4 | AT23: =(AS23/(AS23+AR23))*100 -> 90.214648
Q24: 17 | R24: =VOUT -> 30 | S24: =Q24*$O$12 -> 0.22666667 | T24: =VIN_var -> 24 | U24: =(R24*S24)/(T24*EFF_est) -> 0.31481481 | V24: =IF((S24*R24/T24)<((T24*(1-(T24/R24)))/(2*Lm*Fsw)),1,2) -> 1 | W24: =CHOOSE(V24,SQRT((2*S24*Lm*Fsw*(R24-T24))/((T24)^2)),1-(T24/R24)) -> 0.15518806 | X24: =CHOOSE(V24,(Lm*W24*Fsw)/(R24-T24),1-W24) -> 0.13190985 | Y24: =(T24*W24)/(Lm*Fsw) -> 0.73029674 | Z24: =CHOOSE(V24,Y24,U24+(0.5*Y24)) -> 0.73029674 | AA24: =CHOOSE(V24,Z24*SQRT((W24+X24)/3),SQRT((U24^2)+((Y24^2)/12))) -> 0.22591952 | AB24: 0 | AC24: =(AA24^2)*Rdcr -> 0.0010207926 | AD24: =AB24+AC24 -> 0.0010207926 | AE24: =U24*W24 -> 0.0488555 | AF24: =CHOOSE(V24,Z24*SQRT(W24/3),SQRT(W24*((Z24^2)+((Y24^2)/3)-(Z24*Y24)))) -> 0.16609933 | AG24: =(AF24^2)*RDS_on -> 0.00012690935 | AH24: =((R24*U24)/2)*Fsw*(tr_sw+tf_sw) -> 0.13764255 | AI24: =AG24+AH24 -> 0.13776946 | AJ24: =X24*U24 -> 0.041527175 | AK24: =CHOOSE(V24,Z24*SQRT(X24/3),SQRT(X24*((Z24^2)+((Y24^2)/3)-(Y24*Z24)))) -> 0.15313602 | AL24: =S24*Vd_rect -> 0.13146667 | AM24: =CHOOSE(V24,(R24+Vd_rect)*Qrr*Fsw,(R24+Vd_rect)*Qrr*Fsw) -> 0.22935 | AN24: =AL24+AM24 -> 0.36081667 | AO24: =(AF24^2)*R_cs -> 0.00027588988 | AP24: =Qg_tot*Vcc*Fsw -> 0.1994625 | AQ24: =IQ*T24 -> 0.0108 | AR24: =AO24+AN24+AI24+AD24+AP24+AQ24 -> 0.71014531 | AS24: =R24*S24 -> 6.8 | AT24: =(AS24/(AS24+AR24))*100 -> 90.544187
Q25: 18 | R25: =VOUT -> 30 | S25: =Q25*$O$12 -> 0.24 | T25: =VIN_var -> 24 | U25: =(R25*S25)/(T25*EFF_est) -> 0.33333333 | V25: =IF((S25*R25/T25)<((T25*(1-(T25/R25)))/(2*Lm*Fsw)),1,2) -> 1 | W25: =CHOOSE(V25,SQRT((2*S25*Lm*Fsw*(R25-T25))/((T25)^2)),1-(T25/R25)) -> 0.15968719 | X25: =CHOOSE(V25,(Lm*W25*Fsw)/(R25-T25),1-W25) -> 0.13573412 | Y25: =(T25*W25)/(Lm*Fsw) -> 0.75146915 | Z25: =CHOOSE(V25,Y25,U25+(0.5*Y25)) -> 0.75146915 | AA25: =CHOOSE(V25,Z25*SQRT((W25+X25)/3),SQRT((U25^2)+((Y25^2)/12))) -> 0.23581501 | AB25: 0 | AC25: =(AA25^2)*Rdcr -> 0.0011121743 | AD25: =AB25+AC25 -> 0.0011121743 | AE25: =U25*W25 -> 0.053229065 | AF25: =CHOOSE(V25,Z25*SQRT(W25/3),SQRT(W25*((Z25^2)+((Y25^2)/3)-(Z25*Y25)))) -> 0.17337464 | AG25: =(AF25^2)*RDS_on -> 0.00013827032 | AH25: =((R25*U25)/2)*Fsw*(tr_sw+tf_sw) -> 0.14573917 | AI25: =AG25+AH25 -> 0.14587744 | AJ25: =X25*U25 -> 0.045244705 | AK25: =CHOOSE(V25,Z25*SQRT(X25/3),SQRT(X25*((Z25^2)+((Y25^2)/3)-(Y25*Z25)))) -> 0.15984352 | AL25: =S25*Vd_rect -> 0.1392 | AM25: =CHOOSE(V25,(R25+Vd_rect)*Qrr*Fsw,(R25+Vd_rect)*Qrr*Fsw) -> 0.22935 | AN25: =AL25+AM25 -> 0.36855 | AO25: =(AF25^2)*R_cs -> 0.00030058766 | AP25: =Qg_tot*Vcc*Fsw -> 0.1994625 | AQ25: =IQ*T25 -> 0.0108 | AR25: =AO25+AN25+AI25+AD25+AP25+AQ25 -> 0.7261027 | AS25: =R25*S25 -> 7.2 | AT25: =(AS25/(AS25+AR25))*100 -> 90.839095
Q26: 19 | R26: =VOUT -> 30 | S26: =Q26*$O$12 -> 0.25333333 | T26: =VIN_var -> 24 | U26: =(R26*S26)/(T26*EFF_est) -> 0.35185185 | V26: =IF((S26*R26/T26)<((T26*(1-(T26/R26)))/(2*Lm*Fsw)),1,2) -> 1 | W26: =CHOOSE(V26,SQRT((2*S26*Lm*Fsw*(R26-T26))/((T26)^2)),1-(T26/R26)) -> 0.164063 | X26: =CHOOSE(V26,(Lm*W26*Fsw)/(R26-T26),1-W26) -> 0.13945355 | Y26: =(T26*W26)/(Lm*Fsw) -> 0.77206116 | Z26: =CHOOSE(V26,Y26,U26+(0.5*Y26)) -> 0.77206116 | AA26: =CHOOSE(V26,Z26*SQRT((W26+X26)/3),SQRT((U26^2)+((Y26^2)/12))) -> 0.24557393 | AB26: 0 | AC26: =(AA26^2)*Rdcr -> 0.0012061311 | AD26: =AB26+AC26 -> 0.0012061311 | AE26: =U26*W26 -> 0.057725869 | AF26: =CHOOSE(V26,Z26*SQRT(W26/3),SQRT(W26*((Z26^2)+((Y26^2)/3)-(Z26*Y26)))) -> 0.18054954 | AG26: =(AF26^2)*RDS_on -> 0.00014995143 | AH26: =((R26*U26)/2)*Fsw*(tr_sw+tf_sw) -> 0.15383579 | AI26: =AG26+AH26 -> 0.15398574 | AJ26: =X26*U26 -> 0.049066989 | AK26: =CHOOSE(V26,Z26*SQRT(X26/3),SQRT(X26*((Z26^2)+((Y26^2)/3)-(Y26*Z26)))) -> 0.16645845 | AL26: =S26*Vd_rect -> 0.14693333 | AM26: =CHOOSE(V26,(R26+Vd_rect)*Qrr*Fsw,(R26+Vd_rect)*Qrr*Fsw) -> 0.22935 | AN26: =AL26+AM26 -> 0.37628333 | AO26: =(AF26^2)*R_cs -> 0.00032598138 | AP26: =Qg_tot*Vcc*Fsw -> 0.1994625 | AQ26: =IQ*T26 -> 0.0108 | AR26: =AO26+AN26+AI26+AD26+AP26+AQ26 -> 0.74206369 | AS26: =R26*S26 -> 7.6 | AT26: =(AS26/(AS26+AR26))*100 -> 91.104555
Q27: 20 | R27: =VOUT -> 30 | S27: =Q27*$O$12 -> 0.26666667 | T27: =VIN_var -> 24 | U27: =(R27*S27)/(T27*EFF_est) -> 0.37037037 | V27: =IF((S27*R27/T27)<((T27*(1-(T27/R27)))/(2*Lm*Fsw)),1,2) -> 1 | W27: =CHOOSE(V27,SQRT((2*S27*Lm*Fsw*(R27-T27))/((T27)^2)),1-(T27/R27)) -> 0.16832508 | X27: =CHOOSE(V27,(Lm*W27*Fsw)/(R27-T27),1-W27) -> 0.14307632 | Y27: =(T27*W27)/(Lm*Fsw) -> 0.79211803 | Z27: =CHOOSE(V27,Y27,U27+(0.5*Y27)) -> 0.79211803 | AA27: =CHOOSE(V27,Z27*SQRT((W27+X27)/3),SQRT((U27^2)+((Y27^2)/12))) -> 0.25520522 | AB27: 0 | AC27: =(AA27^2)*Rdcr -> 0.0013025941 | AD27: =AB27+AC27 -> 0.0013025941 | AE27: =U27*W27 -> 0.062342623 | AF27: =CHOOSE(V27,Z27*SQRT(W27/3),SQRT(W27*((Z27^2)+((Y27^2)/3)-(Z27*Y27)))) -> 0.18763061 | AG27: =(AF27^2)*RDS_on -> 0.00016194413 | AH27: =((R27*U27)/2)*Fsw*(tr_sw+tf_sw) -> 0.16193241 | AI27: =AG27+AH27 -> 0.16209435 | AJ27: =X27*U27 -> 0.05299123 | AK27: =CHOOSE(V27,Z27*SQRT(X27/3),SQRT(X27*((Z27^2)+((Y27^2)/3)-(Y27*Z27)))) -> 0.17298688 | AL27: =S27*Vd_rect -> 0.15466667 | AM27: =CHOOSE(V27,(R27+Vd_rect)*Qrr*Fsw,(R27+Vd_rect)*Qrr*Fsw) -> 0.22935 | AN27: =AL27+AM27 -> 0.38401667 | AO27: =(AF27^2)*R_cs -> 0.00035205246 | AP27: =Qg_tot*Vcc*Fsw -> 0.1994625 | AQ27: =IQ*T27 -> 0.0108 | AR27: =AO27+AN27+AI27+AD27+AP27+AQ27 -> 0.75802817 | AS27: =R27*S27 -> 8 | AT27: =(AS27/(AS27+AR27))*100 -> 91.344762
... Q157: 150 | R157: =VOUT -> 30 | S157: =Q157*$O$12 -> 2 | T157: =VIN_var -> 24 | U157: =(R157*S157)/(T157*EFF_est) -> 2.7777778 | V157: =IF((S157*R157/T157)<((T157*(1-(T157/R157)))/(2*Lm*Fsw)),1,2) -> 2 | W157: =CHOOSE(V157,SQRT((2*S157*Lm*Fsw*(R157-T157))/((T157)^2)),1-(T157/R157)) -> 0.2 | X157: =CHOOSE(V157,(Lm*W157*Fsw)/(R157-T157),1-W157) -> 0.8 | Y157: =(T157*W157)/(Lm*Fsw) -> 0.94117647 | Z157: =CHOOSE(V157,Y157,U157+(0.5*Y157)) -> 3.248366 | AA157: =CHOOSE(V157,Z157*SQRT((W157+X157)/3),SQRT((U157^2)+((Y157^2)/12))) -> 2.7910333 | AB157: 0 | AC157: =(AA157^2)*Rdcr -> 0.15579734 | AD157: =AB157+AC157 -> 0.15579734 | AE157: =U157*W157 -> 0.55555556 | AF157: =CHOOSE(V157,Z157*SQRT(W157/3),SQRT(W157*((Z157^2)+((Y157^2)/3)-(Z157*Y157)))) -> 1.2481881 | AG157: =(AF157^2)*RDS_on -> 0.0071666778 | AH157: =((R157*U157)/2)*Fsw*(tr_sw+tf_sw) -> 1.2144931 | AI157: =AG157+AH157 -> 1.2216598 | AJ157: =X157*U157 -> 2.2222222 | AK157: =CHOOSE(V157,Z157*SQRT(X157/3),SQRT(X157*((Z157^2)+((Y157^2)/3)-(Y157*Z157)))) -> 2.4963761 | AL157: =S157*Vd_rect -> 1.16 | AM157: =CHOOSE(V157,(R157+Vd_rect)*Qrr*Fsw,(R157+Vd_rect)*Qrr*Fsw) -> 0.22935 | AN157: =AL157+AM157 -> 1.38935 | AO157: =(AF157^2)*R_cs -> 0.015579734 | AP157: =Qg_tot*Vcc*Fsw -> 0.1994625 | AQ157: =IQ*T157 -> 0.0108 | AR157: =AO157+AN157+AI157+AD157+AP157+AQ157 -> 2.9926493 | AS157: =R157*S157 -> 60 | AT157: =(AS157/(AS157+AR157))*100 -> 95.249209

Sheet Loop_Modeling
A1: EXCEL Variables Names/Calculations | N1: Calculations
B2: Input from user =
B3: Output =
B4: Constant | P4: Plant Transfer Function | AF4: Error Amplifier | AS4: Open Loop Response
Q5: wp_lf | T5: wz_esr | W5: wz_rhp | Z5: Sampling | AC5: Total | AG5: wp0_ea | AJ5: wp1_ea | AM5: wz_ea | AP5: Total | AS5: Total
A6: Variable Name | B6: Value | C6: STD Units | E6: Notes | P6: ADC | Q6: Complex | R6: Gain | S6: Phase | T6: Complex | U6: Gain | V6: Phase | W6: Complex | X6: Gain | Y6: Phase | Z6: Complex | AA6: Gain | AB6: Phase | AC6: COMPLEX | AD6: Gain | AE6: Phase | AF6: ADC_ea | AG6: Complex | AH6: Gain | AI6: Phase | AJ6: Complex | AK6: Gain | AL6: Phase | AM6: Complex | AN6: Gain | AO6: Phase | AP6: COMPLEX | AQ6: Gain | AR6: Phase | AS6: COMPLEX | AT6: Gain | AU6: Phase
N7: Frcoss (VIN)min | O7: =fcross -> 100000 | P7: =COMPLEX(ADC_VINmin,0) -> 29 | Q7: =IMSUM(COMPLEX(1,0),IMDIV(COMPLEX(0,2*PI()*O7),COMPLEX(wp_lf_VINmin,0))) -> 1+4712.3889803847i | R7: =IMABS(Q7) -> 4712.3891 | S7: =IMARGUMENT(Q7) -> 1.5705841 | T7: =IMSUM(COMPLEX(1,0),IMDIV(COMPLEX(0,2*PI()*O7),COMPLEX(wz_esr_VINmin,0))) -> 1+3.1415926535898i | U7: =IMABS(T7) -> 3.2969083 | V7: =IMARGUMENT(T7) -> 1.2626273 | W7: =IMSUB(COMPLEX(1,0),IMDIV(COMPLEX(0,2*PI()*O7),COMPLEX(wz_RHP_VINmin,0))) -> 1-4.00553063332699i | X7: =IMABS(W7) -> 4.1284713 | Y7: =IMARGUMENT(W7) -> -1.3261426 | Z7: =IF(Dc_Mode_Loop="CCM",IMSUM(COMPLEX(1,0),IMDIV(COMPLEX(0,2*PI()*O7),COMPLEX(Q*(wsl/2),0)),IMDIV(IMPOWER(COMPLEX(0,2*PI()*O7),2),IMPOWER(COMPLEX(wsl/2,0),2))),COMPLEX(1,0)) -> 0.928888888888889+0.934937973708323i | AA7: =IMABS(Z7) -> 1.3179316 | AB7: =IMARGUMENT(Z7) -> 0.78864367 | AC7: =(IMDIV(IMPRODUCT(P7,T7,W7),IMPRODUCT(Q7,Z7))) -> -0.0478303414502712-0.0418531995149128i | AD7: =20*LOG(IMABS(AC7)) -> -23.936797 | AE7: =(180/PI())*IMARGUMENT(AC7) -> -138.81295 | AF7: =COMPLEX(Adc_ea,0) -> -0.0000673063927557778 | AG7: =COMPLEX(0,2*PI()*O7*wp0_ea) -> 0.00632591096726841i | AH7: =IMABS(AG7) -> 0.006325911 | AI7: =IMARGUMENT(AG7) -> 1.5707963 | AJ7: =IMSUM(COMPLEX(1,0),IMDIV(COMPLEX(0,2*PI()*O7),COMPLEX(wp1_ea,0))) -> 1+6.3655631836742i | AK7: =IMABS(AJ7) -> 6.4436321 | AL7: =IMARGUMENT(AJ7) -> 1.4149745 | AM7: =IMSUM(COMPLEX(1,0),IMDIV(COMPLEX(0,2*PI()*O7),COMPLEX(wz_ea,0))) -> 1+942.477796076938i | AN7: =IMABS(AM7) -> 942.47833 | AO7: =IMARGUMENT(AM7) -> 1.5697353 | AP7: =IMPRODUCT(AF7,IMDIV(AM7,IMPRODUCT(AG7,AJ7))) -> -0.239883119554354+1.53763094872624i | AQ7: =20*LOG(IMABS(AP7)) -> 3.8414775 | AR7: =(180/PI())*IMARGUMENT(AP7) -> 98.867138 | AS7: =IMPRODUCT(AC7,AP7) -> 0.075828466393785-0.0635055372391125i | AT7: =20*LOG(IMABS(AS7)) -> -20.09532 | AU7: =(180/PI())*IMARGUMENT(AS7) -> -39.945817
N8: Fcross | O8: =fcross -> 100000 | P8: =COMPLEX(Adc,0) -> 87 | Q8: =IMSUM(COMPLEX(1,0),IMDIV(COMPLEX(0,2*PI()*O8),COMPLEX(wp_lf,0))) -> 1+4712.3889803847i | R8: =IMABS(Q8) -> 4712.3891 | S8: =IMARGUMENT(Q8) -> 1.5705841 | T8: =IMSUM(COMPLEX(1,0),IMDIV(COMPLEX(0,2*PI()*O8),COMPLEX(wz_esr,0))) -> 1+3.1415926535898i | U8: =IMABS(T8) -> 3.2969083 | V8: =IMARGUMENT(T8) -> 1.2626273 | W8: =IMSUB(COMPLEX(1,0),IMDIV(COMPLEX(0,2*PI()*O8),COMPLEX(wz_rhp,0))) -> 1-0.445058959258555i | X8: =IMABS(W8) -> 1.0945673 | Y8: =IMARGUMENT(W8) -> -0.41873736 | Z8: =IF(Dc_Mode_Loop="CCM",IMSUM(COMPLEX(1,0),IMDIV(COMPLEX(0,2*PI()*O8),COMPLEX(Q*(wsl/2),0)),IMDIV(IMPOWER(COMPLEX(0,2*PI()*O8),2),IMPOWER(COMPLEX(wsl/2,0),2))),COMPLEX(1,0)) -> 0.928888888888889+0.934937973708323i | AA8: =IMABS(Z8) -> 1.3179316 | AB8: =IMARGUMENT(Z8) -> 0.78864367 | AC8: =(IMDIV(IMPRODUCT(P8,T8,W8),IMPRODUCT(Q8,Z8))) -> 0.00280207324053262-0.050473842382442i | AD8: =20*LOG(IMABS(AC8)) -> -25.925308 | AE8: =(180/PI())*IMARGUMENT(AC8) -> -86.822466 | AF8: =COMPLEX(Adc_ea,0) -> -0.0000673063927557778 | AG8: =COMPLEX(0,2*PI()*O8*wp0_ea) -> 0.00632591096726841i | AH8: =IMABS(AG8) -> 0.006325911 | AI8: =IMARGUMENT(AG8) -> 1.5707963 | AJ8: =IMSUM(COMPLEX(1,0),IMDIV(COMPLEX(0,2*PI()*O8),COMPLEX(wp1_ea,0))) -> 1+6.3655631836742i | AK8: =IMABS(AJ8) -> 6.4436321 | AL8: =IMARGUMENT(AJ8) -> 1.4149745 | AM8: =IMSUM(COMPLEX(1,0),IMDIV(COMPLEX(0,2*PI()*O8),COMPLEX(wz_ea,0))) -> 1+942.477796076938i | AN8: =IMABS(AM8) -> 942.47833 | AO8: =IMARGUMENT(AM8) -> 1.5697353 | AP8: =IMPRODUCT(AF8,IMDIV(AM8,IMPRODUCT(AG8,AJ8))) -> -0.239883119554354+1.53763094872624i | AQ8: =20*LOG(IMABS(AP8)) -> 3.8414775 | AR8: =(180/PI())*IMARGUMENT(AP8) -> 98.867138 | AS8: =IMPRODUCT(AC8,AP8) -> 0.0769379720782143+0.0164163773018355i | AT8: =20*LOG(IMABS(AS8)) -> -22.083831 | AU8: =(180/PI())*IMARGUMENT(AS8) -> 12.044672
A9: Input Parameters | N9: wz_RHP | O9: =wz_rhp/(2*PI()) -> 224689.33 | P9: =COMPLEX(Adc,0) -> 87 | Q9: =IMSUM(COMPLEX(1,0),IMDIV(COMPLEX(0,2*PI()*O9),COMPLEX(wp_lf,0))) -> 1+10588.2352941177i | R9: =IMABS(Q9) -> 10588.235 | S9: =IMARGUMENT(Q9) -> 1.5707019 | T9: =IMSUM(COMPLEX(1,0),IMDIV(COMPLEX(0,2*PI()*O9),COMPLEX(wz_esr,0))) -> 1+7.05882352941175i | U9: =IMABS(T9) -> 7.129305 | V9: =IMARGUMENT(T9) -> 1.4300661 | W9: =IMSUB(COMPLEX(1,0),IMDIV(COMPLEX(0,2*PI()*O9),COMPLEX(wz_rhp,0))) -> 1-i | X9: =IMABS(W9) -> 1.4142136 | Y9: =IMARGUMENT(W9) -> -0.78539816 | Z9: =IF(Dc_Mode_Loop="CCM",IMSUM(COMPLEX(1,0),IMDIV(COMPLEX(0,2*PI()*O9),COMPLEX(Q*(wsl/2),0)),IMDIV(IMPOWER(COMPLEX(0,2*PI()*O9),2),IMPOWER(COMPLEX(wsl/2,0),2))),COMPLEX(1,0)) -> 0.640993453115038+2.10070588235294i | AA9: =IMABS(Z9) -> 2.1963237 | AB9: =IMARGUMENT(Z9) -> 1.2746376 | AC9: =(IMDIV(IMPRODUCT(P9,T9,W9),IMPRODUCT(Q9,Z9))) -> -0.0222182146293106-0.0304808575730229i | AD9: =20*LOG(IMABS(AC9)) -> -28.46877 | AE9: =(180/PI())*IMARGUMENT(AC9) -> -126.08919 | AF9: =COMPLEX(Adc_ea,0) -> -0.0000673063927557778 | AG9: =COMPLEX(0,2*PI()*O9*wp0_ea) -> 0.0142136470588235i | AH9: =IMABS(AG9) -> 0.014213647 | AI9: =IMARGUMENT(AG9) -> 1.5707963 | AJ9: =IMSUM(COMPLEX(1,0),IMDIV(COMPLEX(0,2*PI()*O9),COMPLEX(wp1_ea,0))) -> 1+14.3027413587604i | AK9: =IMABS(AJ9) -> 14.337657 | AL9: =IMARGUMENT(AJ9) -> 1.5009933 | AM9: =IMSUM(COMPLEX(1,0),IMDIV(COMPLEX(0,2*PI()*O9),COMPLEX(wz_ea,0))) -> 1+2117.64705882352i | AN9: =IMABS(AM9) -> 2117.6473 | AO9: =IMARGUMENT(AM9) -> 1.5703241 | AP9: =IMPRODUCT(AF9,IMDIV(AM9,IMPRODUCT(AG9,AJ9))) -> -0.0484512273770859+0.69772070955857i | AQ9: =20*LOG(IMABS(AP9)) -> -3.1054755 | AR9: =(180/PI())*IMARGUMENT(AP9) -> 93.972365 | AS9: =IMPRODUCT(AC9,AP9) -> 0.0223436253427209-0.0140252735153681i | AT9: =20*LOG(IMABS(AS9)) -> -31.574245 | AU9: =(180/PI())*IMARGUMENT(AS9) -> -32.116823
A10: VIN_min | B10: =VIN_min -> 8 | C10: V | E10: Minimum input voltage | N10: wz_esr | O10: =wz_esr/(2*PI()) -> 31830.989 | P10: =COMPLEX(Adc,0) -> 87 | Q10: =IMSUM(COMPLEX(1,0),IMDIV(COMPLEX(0,2*PI()*O10),COMPLEX(wp_lf,0))) -> 1+1500i | R10: =IMABS(Q10) -> 1500.0003 | S10: =IMARGUMENT(Q10) -> 1.5701297 | T10: =IMSUM(COMPLEX(1,0),IMDIV(COMPLEX(0,2*PI()*O10),COMPLEX(wz_esr,0))) -> 1+i | U10: =IMABS(T10) -> 1.4142136 | V10: =IMARGUMENT(T10) -> 0.78539816 | W10: =IMSUB(COMPLEX(1,0),IMDIV(COMPLEX(0,2*PI()*O10),COMPLEX(wz_rhp,0))) -> 1-0.141666666666667i | X10: =IMABS(W10) -> 1.0099849 | Y10: =IMARGUMENT(W10) -> -0.14073019 | Z10: =IF(Dc_Mode_Loop="CCM",IMSUM(COMPLEX(1,0),IMDIV(COMPLEX(0,2*PI()*O10),COMPLEX(Q*(wsl/2),0)),IMDIV(IMPOWER(COMPLEX(0,2*PI()*O10),2),IMPOWER(COMPLEX(wsl/2,0),2))),COMPLEX(1,0)) -> 0.9927949380521+0.2976i | AA10: =IMABS(Z10) -> 1.0364398 | AB10: =IMARGUMENT(Z10) -> 0.2912364 | AC10: =(IMDIV(IMPRODUCT(P10,T10,W10),IMPRODUCT(Q10,Z10))) -> 0.0277155485660217-0.0749717718768766i | AD10: =20*LOG(IMABS(AC10)) -> -21.945727 | AE10: =(180/PI())*IMARGUMENT(AC10) -> -69.711666 | AF10: =COMPLEX(Adc_ea,0) -> -0.0000673063927557778 | AG10: =COMPLEX(0,2*PI()*O10*wp0_ea) -> 0.0020136i | AH10: =IMABS(AG10) -> 0.0020136 | AI10: =IMARGUMENT(AG10) -> 1.5707963 | AJ10: =IMSUM(COMPLEX(1,0),IMDIV(COMPLEX(0,2*PI()*O10),COMPLEX(wp1_ea,0))) -> 1+2.02622169249106i | AK10: =IMABS(AJ10) -> 2.2595518 | AL10: =IMARGUMENT(AJ10) -> 1.1123386 | AM10: =IMSUM(COMPLEX(1,0),IMDIV(COMPLEX(0,2*PI()*O10),COMPLEX(wz_ea,0))) -> 1+300i | AN10: =IMABS(AM10) -> 300.00167 | AO10: =IMARGUMENT(AM10) -> 1.567463 | AP10: =IMPRODUCT(AF10,IMDIV(AM10,IMPRODUCT(AG10,AJ10))) -> -1.9508171099829+3.98621384658622i | AQ10: =20*LOG(IMABS(AP10)) -> 12.94369 | AR10: =(180/PI())*IMARGUMENT(AP10) -> 116.07671 | AS10: =IMPRODUCT(AC10,AP10) -> 0.244785548803552+0.256736318802754i | AT10: =20*LOG(IMABS(AS10)) -> -9.0020372 | AU10: =(180/PI())*IMARGUMENT(AS10) -> 46.365043
A11: VIN_nom | B11: =VIN_nom -> 24 | C11: V | E11: Nominal input voltage | N11: wp_lf | O11: =wp_lf/(2*PI()) -> 21.220659 | P11: =COMPLEX(Adc,0) -> 87 | Q11: =IMSUM(COMPLEX(1,0),IMDIV(COMPLEX(0,2*PI()*O11),COMPLEX(wp_lf,0))) -> 1+i | R11: =IMABS(Q11) -> 1.4142136 | S11: =IMARGUMENT(Q11) -> 0.78539816 | T11: =IMSUM(COMPLEX(1,0),IMDIV(COMPLEX(0,2*PI()*O11),COMPLEX(wz_esr,0))) -> 1+0.000666666666666665i | U11: =IMABS(T11) -> 1.0000002 | V11: =IMARGUMENT(T11) -> 0.00066666657 | W11: =IMSUB(COMPLEX(1,0),IMDIV(COMPLEX(0,2*PI()*O11),COMPLEX(wz_rhp,0))) -> 1-0.0000944444444444444i | X11: =IMABS(W11) -> 1 | Y11: =IMARGUMENT(W11) -> -9.4444444e-05 | Z11: =IF(Dc_Mode_Loop="CCM",IMSUM(COMPLEX(1,0),IMDIV(COMPLEX(0,2*PI()*O11),COMPLEX(Q*(wsl/2),0)),IMDIV(IMPOWER(COMPLEX(0,2*PI()*O11),2),IMPOWER(COMPLEX(wsl/2,0),2))),COMPLEX(1,0)) -> 0.99999999679775+0.0001984i | AA11: =IMABS(Z11) -> 1 | AB11: =IMARGUMENT(Z11) -> 0.0001984 | AC11: =(IMDIV(IMPRODUCT(P11,T11,W11),IMPRODUCT(Q11,Z11))) -> 43.5162673699295-43.4837448389142i | AD11: =20*LOG(IMABS(AC11)) -> 35.780087 | AE11: =(180/PI())*IMARGUMENT(AC11) -> -44.978582 | AF11: =COMPLEX(Adc_ea,0) -> -0.0000673063927557778 | AG11: =COMPLEX(0,2*PI()*O11*wp0_ea) -> 0.0000013424i | AH11: =IMABS(AG11) -> 1.3424e-06 | AI11: =IMARGUMENT(AG11) -> 1.5707963 | AJ11: =IMSUM(COMPLEX(1,0),IMDIV(COMPLEX(0,2*PI()*O11),COMPLEX(wp1_ea,0))) -> 1+0.0013508144616607i | AK11: =IMABS(AJ11) -> 1.0000009 | AL11: =IMARGUMENT(AJ11) -> 0.0013508136 | AM11: =IMSUM(COMPLEX(1,0),IMDIV(COMPLEX(0,2*PI()*O11),COMPLEX(wz_ea,0))) -> 1+0.199999999999999i | AN11: =IMABS(AM11) -> 1.0198039 | AO11: =IMARGUMENT(AM11) -> 0.19739556 | AP11: =IMPRODUCT(AF11,IMDIV(AM11,IMPRODUCT(AG11,AJ11))) -> -9.96002361860185+50.1523045281631i | AQ11: =20*LOG(IMABS(AP11)) -> 34.173813 | AR11: =(180/PI())*IMARGUMENT(AP11) -> 101.23254 | AS11: =IMPRODUCT(AC11,AP11) -> 1747.38696238827+2615.54021868651i | AT11: =20*LOG(IMABS(AS11)) -> 69.9539 | AU11: =(180/PI())*IMARGUMENT(AS11) -> 56.253955 | AX11: XOVER SEARCH
A12: VIN_max | B12: =VIN_max -> 24 | C12: V | E12: Maximum input voltage | N12: wz_ea | O12: =wz_ea/(2*PI()) -> 106.1033 | P12: =COMPLEX(Adc,0) -> 87 | Q12: =IMSUM(COMPLEX(1,0),IMDIV(COMPLEX(0,2*PI()*O12),COMPLEX(wp_lf,0))) -> 1+5.00000000000002i | R12: =IMABS(Q12) -> 5.0990195 | S12: =IMARGUMENT(Q12) -> 1.3734008 | T12: =IMSUM(COMPLEX(1,0),IMDIV(COMPLEX(0,2*PI()*O12),COMPLEX(wz_esr,0))) -> 1+0.00333333333333333i | U12: =IMABS(T12) -> 1.0000056 | V12: =IMARGUMENT(T12) -> 0.003333321 | W12: =IMSUB(COMPLEX(1,0),IMDIV(COMPLEX(0,2*PI()*O12),COMPLEX(wz_rhp,0))) -> 1-0.000472222222222223i | X12: =IMABS(W12) -> 1.0000001 | Y12: =IMARGUMENT(W12) -> -0.00047222219 | Z12: =IF(Dc_Mode_Loop="CCM",IMSUM(COMPLEX(1,0),IMDIV(COMPLEX(0,2*PI()*O12),COMPLEX(Q*(wsl/2),0)),IMDIV(IMPOWER(COMPLEX(0,2*PI()*O12),2),IMPOWER(COMPLEX(wsl/2,0),2))),COMPLEX(1,0)) -> 0.999999919943756+0.000992000000000001i | AA12: =IMABS(Z12) -> 1.0000004 | AB12: =IMARGUMENT(Z12) -> 0.00099199975 | AC12: =(IMDIV(IMPRODUCT(P12,T12,W12),IMPRODUCT(Q12,Z12))) -> 3.3774371963603-16.7245736048959i | AD12: =20*LOG(IMABS(AC12)) -> 24.640697 | AE12: =(180/PI())*IMARGUMENT(AC12) -> -78.582976 | AF12: =COMPLEX(Adc_ea,0) -> -0.0000673063927557778 | AG12: =COMPLEX(0,2*PI()*O12*wp0_ea) -> 0.000006712i | AH12: =IMABS(AG12) -> 6.712e-06 | AI12: =IMARGUMENT(AG12) -> 1.5707963 | AJ12: =IMSUM(COMPLEX(1,0),IMDIV(COMPLEX(0,2*PI()*O12),COMPLEX(wp1_ea,0))) -> 1+0.00675407230830354i | AK12: =IMABS(AJ12) -> 1.0000228 | AL12: =IMARGUMENT(AJ12) -> 0.0067539696 | AM12: =IMSUM(COMPLEX(1,0),IMDIV(COMPLEX(0,2*PI()*O12),COMPLEX(wz_ea,0))) -> 1+i | AN12: =IMABS(AM12) -> 1.4142136 | AO12: =IMARGUMENT(AM12) -> 0.78539816 | AP12: =IMPRODUCT(AF12,IMDIV(AM12,IMPRODUCT(AG12,AJ12))) -> -9.95958746124532+10.0950378507182i | AQ12: =20*LOG(IMABS(AP12)) -> 23.034189 | AR12: =(180/PI())*IMARGUMENT(AP12) -> 134.61303 | AS12: =IMPRODUCT(AC12,AP12) -> 135.197322426533+200.665209905676i | AT12: =20*LOG(IMABS(AS12)) -> 47.674886 | AU12: =(180/PI())*IMARGUMENT(AS12) -> 56.03005 | AX12: xover | AY12: =SUM(AX19:AX559)/1000 -> 14.454398
A13: Fsw | B13: =Fsw -> 750000 | C13: Hz | E13: Switching frequnecy | N13: wp1_ea | O13: =wp1_ea/(2*PI()) -> 15709.529 | P13: =COMPLEX(Adc,0) -> 87 | Q13: =IMSUM(COMPLEX(1,0),IMDIV(COMPLEX(0,2*PI()*O13),COMPLEX(wp_lf,0))) -> 1+740.294117647061i | R13: =IMABS(Q13) -> 740.29479 | S13: =IMARGUMENT(Q13) -> 1.5694455 | T13: =IMSUM(COMPLEX(1,0),IMDIV(COMPLEX(0,2*PI()*O13),COMPLEX(wz_esr,0))) -> 1+0.493529411764706i | U13: =IMABS(T13) -> 1.1151553 | V13: =IMARGUMENT(T13) -> 0.45845775 | W13: =IMSUB(COMPLEX(1,0),IMDIV(COMPLEX(0,2*PI()*O13),COMPLEX(wz_rhp,0))) -> 1-0.0699166666666668i | X13: =IMABS(W13) -> 1.0024412 | Y13: =IMARGUMENT(W13) -> -0.069803074 | Z13: =IF(Dc_Mode_Loop="CCM",IMSUM(COMPLEX(1,0),IMDIV(COMPLEX(0,2*PI()*O13),COMPLEX(Q*(wsl/2),0)),IMDIV(IMPOWER(COMPLEX(0,2*PI()*O13),2),IMPOWER(COMPLEX(wsl/2,0),2))),COMPLEX(1,0)) -> 0.998245053836876+0.146874352941177i | AA13: =IMABS(Z13) -> 1.0089922 | AB13: =IMARGUMENT(Z13) -> 0.14608444 | AC13: =(IMDIV(IMPRODUCT(P13,T13,W13),IMPRODUCT(Q13,Z13))) -> 0.0314452564948859-0.126348792096567i | AD13: =20*LOG(IMABS(AC13)) -> -17.70758 | AE13: =(180/PI())*IMARGUMENT(AC13) -> -76.024353 | AF13: =COMPLEX(Adc_ea,0) -> -0.0000673063927557778 | AG13: =COMPLEX(0,2*PI()*O13*wp0_ea) -> 0.000993770823529412i | AH13: =IMABS(AG13) -> 0.00099377082 | AI13: =IMARGUMENT(AG13) -> 1.5707963 | AJ13: =IMSUM(COMPLEX(1,0),IMDIV(COMPLEX(0,2*PI()*O13),COMPLEX(wp1_ea,0))) -> 1+i | AK13: =IMABS(AJ13) -> 1.4142136 | AL13: =IMARGUMENT(AJ13) -> 0.78539816 | AM13: =IMSUM(COMPLEX(1,0),IMDIV(COMPLEX(0,2*PI()*O13),COMPLEX(wz_ea,0))) -> 1+148.058823529412i | AN13: =IMABS(AM13) -> 148.0622 | AO13: =IMARGUMENT(AM13) -> 1.5640424 | AP13: =IMPRODUCT(AF13,IMDIV(AM13,IMPRODUCT(AG13,AJ13))) -> -4.98002089632705+5.0477491805171i | AQ13: =20*LOG(IMABS(AP13)) -> 17.013986 | AR13: =(180/PI())*IMARGUMENT(AP13) -> 134.61303 | AS13: =IMPRODUCT(AC13,AP13) -> 0.481178977329876+0.787947392569796i | AT13: =20*LOG(IMABS(AS13)) -> -0.69359462 | AU13: =(180/PI())*IMARGUMENT(AS13) -> 58.588673
A14: Dc_Mode_Loop_Loop | B14: CCM | E14: Duty Cycle mode for Loop Comenstation | AX14: phase margin | AY14: =SUM(AY19:AY559) -> 60.080562
O15: Selected VIN | P15: =B17 -> 24 | Q15: V
A16: Plant Parameters | P16: Plant Transfer Function | AF16: Error Amplifier | AS16: Open Loop Response
A17: VIN_VAR | B17: =VIN_var -> 24 | C17: V | E17: Variable input voltage | Q17: wp_lf | T17: wz_esr | W17: wz_rhp | Z17: Sampling | AC17: Total | AG17: wp0_ea | AJ17: wp1_ea | AM17: wz_ea | AP17: Total | AS17: Total
A18: IOUT_VAR | C18: A | E18: Variable output current (Need to add this in | O18: Frequency | P18: ADC | Q18: Complex | R18: Gain | S18: Phase | T18: Complex | U18: Gain | V18: Phase | W18: Complex | X18: Gain | Y18: Phase | Z18: Complex | AA18: Gain | AB18: Phase | AC18: COMPLEX | AD18: Gain | AE18: Phase | AF18: ADC_ea | AG18: Complex | AH18: Gain | AI18: Phase | AJ18: Complex | AK18: Gain | AL18: Phase | AM18: Complex | AN18: Gain | AO18: Phase | AP18: COMPLEX | AQ18: Gain | AR18: Phase | AS18: COMPLEX | AT18: Gain | AU18: Phase | AX18: Gain Cross | AY18: Phase Cross
N19: 1 | O19: =10^(1+(N19/100)) -> 10.23293 | P19: =COMPLEX(Adc,0) -> 87 | Q19: =IMSUM(COMPLEX(1,0),IMDIV(COMPLEX(0,2*PI()*O19),COMPLEX(wp_lf,0))) -> 1+0.482215462052872i | R19: =IMABS(Q19) -> 1.1101945 | S19: =IMARGUMENT(Q19) -> 0.44931902 | T19: =IMSUM(COMPLEX(1,0),IMDIV(COMPLEX(0,2*PI()*O19),COMPLEX(wz_esr,0))) -> 1+0.000321476974701914i | U19: =IMABS(T19) -> 1.0000001 | V19: =IMARGUMENT(T19) -> 0.00032147696 | W19: =IMSUB(COMPLEX(1,0),IMDIV(COMPLEX(0,2*PI()*O19),COMPLEX(wz_rhp,0))) -> 1-0.0000455425714161045i | X19: =IMABS(W19) -> 1 | Y19: =IMARGUMENT(W19) -> -4.5542571e-05 | Z19: =IF(Dc_Mode_Loop="CCM",IMSUM(COMPLEX(1,0),IMDIV(COMPLEX(0,2*PI()*O19),COMPLEX(Q*(wsl/2),0)),IMDIV(IMPOWER(COMPLEX(0,2*PI()*O19),2),IMPOWER(COMPLEX(wsl/2,0),2))),COMPLEX(1,0)) -> 0.999999999255375+0.0000956715476712895i | AA19: =IMABS(Z19) -> 1 | AB19: =IMARGUMENT(Z19) -> 9.5671547e-05 | AC19: =(IMDIV(IMPRODUCT(P19,T19,W19),IMPRODUCT(Q19,Z19))) -> 70.5925549020351-34.0251386113991i | AD19: =20*LOG(IMABS(AC19)) -> 37.882404 | AE19: =(180/PI())*IMARGUMENT(AC19) -> -25.733755 | AF19: =COMPLEX(Adc_ea,0) -> -0.0000673063927557778 | AG19: =COMPLEX(0,2*PI()*O19*wp0_ea) -> 6.47326036259773E-07i | AH19: =IMABS(AG19) -> 6.4732604e-07 | AI19: =IMARGUMENT(AG19) -> 1.5707963 | AJ19: =IMSUM(COMPLEX(1,0),IMDIV(COMPLEX(0,2*PI()*O19),COMPLEX(wp1_ea,0))) -> 1+0.000651383619777417i | AK19: =IMABS(AJ19) -> 1.0000002 | AL19: =IMARGUMENT(AJ19) -> 0.00065138353 | AM19: =IMSUM(COMPLEX(1,0),IMDIV(COMPLEX(0,2*PI()*O19),COMPLEX(wz_ea,0))) -> 1+0.096443092410574i | AN19: =IMABS(AM19) -> 1.0046399 | AO19: =IMARGUMENT(AM19) -> 0.096145736 | AP19: =IMPRODUCT(AF19,IMDIV(AM19,IMPRODUCT(AG19,AJ19))) -> -9.96003756660395+103.982519952388i | AQ19: =20*LOG(IMABS(AP19)) -> 40.378871 | AR19: =(180/PI())*IMARGUMENT(AP19) -> 95.471423 | AS19: =IMPRODUCT(AC19,AP19) -> 2834.91515579575+7679.28340736935i | AT19: =20*LOG(IMABS(AS19)) -> 78.261275 | AU19: =(180/PI())*IMARGUMENT(AS19) -> 69.737668 | AX19: =SUM((AT20<0)*(AT19>0))*O19 -> 0 | AY19: =IF(AX19>0,AU19,0) -> 0
A20: VOUT | B20: =VOUT -> 30 | C20: V | E20: Output Voltage | N20: 2 | O20: =10^(1+(N20/100)) -> 10.471285 | P20: =COMPLEX(Adc,0) -> 87 | Q20: =IMSUM(COMPLEX(1,0),IMDIV(COMPLEX(0,2*PI()*O20),COMPLEX(wp_lf,0))) -> 1+0.493447703088129i | R20: =IMABS(Q20) -> 1.1151191 | S20: =IMARGUMENT(Q20) -> 0.45839205 | T20: =IMSUM(COMPLEX(1,0),IMDIV(COMPLEX(0,2*PI()*O20),COMPLEX(wz_esr,0))) -> 1+0.000328965135392085i | U20: =IMABS(T20) -> 1.0000001 | V20: =IMARGUMENT(T20) -> 0.00032896512 | W20: =IMSUB(COMPLEX(1,0),IMDIV(COMPLEX(0,2*PI()*O20),COMPLEX(wz_rhp,0))) -> 1-0.0000466033941805455i | X20: =IMABS(W20) -> 1 | Y20: =IMARGUMENT(W20) -> -4.6603394e-05 | Z20: =IF(Dc_Mode_Loop="CCM",IMSUM(COMPLEX(1,0),IMDIV(COMPLEX(0,2*PI()*O20),COMPLEX(Q*(wsl/2),0)),IMDIV(IMPOWER(COMPLEX(0,2*PI()*O20),2),IMPOWER(COMPLEX(wsl/2,0),2))),COMPLEX(1,0)) -> 0.999999999220282+0.0000979000242926847i | AA20: =IMABS(Z20) -> 1 | AB20: =IMARGUMENT(Z20) -> 9.7900024e-05 | AC20: =(IMDIV(IMPRODUCT(P20,T20,W20),IMPRODUCT(Q20,Z20))) -> 69.9707093951138-34.5108376653725i | AD20: =20*LOG(IMABS(AC20)) -> 37.84396 | AE20: =(180/PI())*IMARGUMENT(AC20) -> -26.253361 | AF20: =COMPLEX(Adc_ea,0) -> -0.0000673063927557778 | AG20: =COMPLEX(0,2*PI()*O20*wp0_ea) -> 6.62404196625503E-07i | AH20: =IMABS(AG20) -> 6.624042e-07 | AI20: =IMARGUMENT(AG20) -> 1.5707963 | AJ20: =IMSUM(COMPLEX(1,0),IMDIV(COMPLEX(0,2*PI()*O20),COMPLEX(wp1_ea,0))) -> 1+0.000666556293404702i | AK20: =IMABS(AJ20) -> 1.0000002 | AL20: =IMARGUMENT(AJ20) -> 0.00066655619 | AM20: =IMSUM(COMPLEX(1,0),IMDIV(COMPLEX(0,2*PI()*O20),COMPLEX(wz_ea,0))) -> 1+0.0986895406176256i | AN20: =IMABS(AM20) -> 1.004858 | AO20: =IMARGUMENT(AM20) -> 0.098371 | AP20: =IMPRODUCT(AF20,IMDIV(AM20,IMPRODUCT(AG20,AJ20))) -> -9.96003736743646+101.615887626999i | AQ20: =20*LOG(IMABS(AP20)) -> 40.180757 | AR20: =(180/PI())*IMARGUMENT(AP20) -> 95.598052 | AS20: =IMPRODUCT(AC20,AP20) -> 2809.93852191673+7453.86497580393i | AT20: =20*LOG(IMABS(AS20)) -> 78.024717 | AU20: =(180/PI())*IMARGUMENT(AS20) -> 69.344692 | AX20: =SUM((AT21<0)*(AT20>0))*O20 -> 0 | AY20: =IF(AX20>0,AU20,0) -> 0
